Workbook

Sheet ОБЩИЙ
A1: AKO PLAY — каталог комплектующих для детских площадок
A2: Сводка по наполнению каталога и заказам. Всё считается само — заполняй листы категорий и «ЗАКАЗЫ».
A4: Категория (лист) | B4: Префикс | C4: Позиций заведено | D4: Готово к сайту | E4: На сайте | F4: ТОП (цель 4–5) | G4: Без фото | H4: Без схемы | I4: Без цены | J4: Без поставщика | K4: Всего шт (все цвета) | L4: Заказано, шт | M4: Пришло, шт | N4: Себестоимость заказов, ₸ | O4: Выручка план (без НДС), ₸ | P4: Прибыль план, ₸ | Q4: Маржа, %
A5: КАНАТЫ | B5: AKO-KN | C5: =COUNTIF(КАНАТЫ!$E$3:$E$302,"?*") -> 4 | D5: =COUNTIF(КАНАТЫ!$B$3:$B$302,"Готов к сайту") -> 0 | E5: =COUNTIF(КАНАТЫ!$B$3:$B$302,"На сайте") -> 1 | F5: =COUNTIF(КАНАТЫ!$D$3:$D$302,"Да") -> 1 | G5: =COUNTIFS(КАНАТЫ!$E$3:$E$302,"?*",КАНАТЫ!$L$3:$L$302,"<>Да") -> 4 | H5: =COUNTIFS(КАНАТЫ!$E$3:$E$302,"?*",КАНАТЫ!$M$3:$M$302,"<>Да") -> 4 | I5: =COUNTIFS(КАНАТЫ!$E$3:$E$302,"?*",КАНАТЫ!$AT$3:$AT$302,"") -> 0 | J5: =COUNTIFS(КАНАТЫ!$E$3:$E$302,"?*",КАНАТЫ!$BB$3:$BB$302,"") -> 0 | K5: =SUM(КАНАТЫ!$AK$3:$AK$302) -> 23000 | L5: =SUM(КАНАТЫ!$BN$3:$BN$302) -> 23000 | M5: =SUM(КАНАТЫ!$BO$3:$BO$302) -> 0 | N5: =SUMIF(ЗАКАЗЫ!$F$3:$F$500,"AKO-KN-*",ЗАКАЗЫ!$Y$3:$Y$500) -> 13233000 | O5: =SUMIF(ЗАКАЗЫ!$F$3:$F$500,"AKO-KN-*",ЗАКАЗЫ!$AH$3:$AH$500) -> 33150000 | P5: =SUMIF(ЗАКАЗЫ!$F$3:$F$500,"AKO-KN-*",ЗАКАЗЫ!$AI$3:$AI$500) -> 19917000 | Q5: =IF(N(O5)=0,"",P5/O5) -> 0.60081448
A6: ГИЛЬЗЫ И ВТУЛКИ | B6: AKO-GV | C6: =COUNTIF('ГИЛЬЗЫ И ВТУЛКИ'!$E$3:$E$302,"?*") -> 13 | D6: =COUNTIF('ГИЛЬЗЫ И ВТУЛКИ'!$B$3:$B$302,"Готов к сайту") -> 1 | E6: =COUNTIF('ГИЛЬЗЫ И ВТУЛКИ'!$B$3:$B$302,"На сайте") -> 0 | F6: =COUNTIF('ГИЛЬЗЫ И ВТУЛКИ'!$D$3:$D$302,"Да") -> 0 | G6: =COUNTIFS('ГИЛЬЗЫ И ВТУЛКИ'!$E$3:$E$302,"?*",'ГИЛЬЗЫ И ВТУЛКИ'!$L$3:$L$302,"<>Да") -> 13 | H6: =COUNTIFS('ГИЛЬЗЫ И ВТУЛКИ'!$E$3:$E$302,"?*",'ГИЛЬЗЫ И ВТУЛКИ'!$M$3:$M$302,"<>Да") -> 13 | I6: =COUNTIFS('ГИЛЬЗЫ И ВТУЛКИ'!$E$3:$E$302,"?*",'ГИЛЬЗЫ И ВТУЛКИ'!$AT$3:$AT$302,"") -> 0 | J6: =COUNTIFS('ГИЛЬЗЫ И ВТУЛКИ'!$E$3:$E$302,"?*",'ГИЛЬЗЫ И ВТУЛКИ'!$BB$3:$BB$302,"") -> 0 | K6: =SUM('ГИЛЬЗЫ И ВТУЛКИ'!$AK$3:$AK$302) -> 17600 | L6: =SUM('ГИЛЬЗЫ И ВТУЛКИ'!$BN$3:$BN$302) -> 17600 | M6: =SUM('ГИЛЬЗЫ И ВТУЛКИ'!$BO$3:$BO$302) -> 0 | N6: =SUMIF(ЗАКАЗЫ!$F$3:$F$500,"AKO-GV-*",ЗАКАЗЫ!$Y$3:$Y$500) -> 4840500 | O6: =SUMIF(ЗАКАЗЫ!$F$3:$F$500,"AKO-GV-*",ЗАКАЗЫ!$AH$3:$AH$500) -> 13581700 | P6: =SUMIF(ЗАКАЗЫ!$F$3:$F$500,"AKO-GV-*",ЗАКАЗЫ!$AI$3:$AI$500) -> 8741200 | Q6: =IF(N(O6)=0,"",P6/O6) -> 0.64360132
A7: Изделия для каната | B7: AKO-IK | C7: =COUNTIF('Изделия для каната'!$E$3:$E$302,"?*") -> 17 | D7: =COUNTIF('Изделия для каната'!$B$3:$B$302,"Готов к сайту") -> 0 | E7: =COUNTIF('Изделия для каната'!$B$3:$B$302,"На сайте") -> 0 | F7: =COUNTIF('Изделия для каната'!$D$3:$D$302,"Да") -> 0 | G7: =COUNTIFS('Изделия для каната'!$E$3:$E$302,"?*",'Изделия для каната'!$L$3:$L$302,"<>Да") -> 17 | H7: =COUNTIFS('Изделия для каната'!$E$3:$E$302,"?*",'Изделия для каната'!$M$3:$M$302,"<>Да") -> 17 | I7: =COUNTIFS('Изделия для каната'!$E$3:$E$302,"?*",'Изделия для каната'!$AT$3:$AT$302,"") -> 0 | J7: =COUNTIFS('Изделия для каната'!$E$3:$E$302,"?*",'Изделия для каната'!$BB$3:$BB$302,"") -> 0 | K7: =SUM('Изделия для каната'!$AK$3:$AK$302) -> 34000 | L7: =SUM('Изделия для каната'!$BN$3:$BN$302) -> 34000 | M7: =SUM('Изделия для каната'!$BO$3:$BO$302) -> 0 | N7: =SUMIF(ЗАКАЗЫ!$F$3:$F$500,"AKO-IK-*",ЗАКАЗЫ!$Y$3:$Y$500) -> 5628500 | O7: =SUMIF(ЗАКАЗЫ!$F$3:$F$500,"AKO-IK-*",ЗАКАЗЫ!$AH$3:$AH$500) -> 11914500 | P7: =SUMIF(ЗАКАЗЫ!$F$3:$F$500,"AKO-IK-*",ЗАКАЗЫ!$AI$3:$AI$500) -> 6286000 | Q7: =IF(N(O7)=0,"",P7/O7) -> 0.52759243
A8: Гимнастические кольца и подвесы | B8: AKO-GK | C8: =COUNTIF('Гимнастические кольца и подвесы'!$E$3:$E$302,"?*") -> 4 | D8: =COUNTIF('Гимнастические кольца и подвесы'!$B$3:$B$302,"Готов к сайту") -> 0 | E8: =COUNTIF('Гимнастические кольца и подвесы'!$B$3:$B$302,"На сайте") -> 0 | F8: =COUNTIF('Гимнастические кольца и подвесы'!$D$3:$D$302,"Да") -> 0 | G8: =COUNTIFS('Гимнастические кольца и подвесы'!$E$3:$E$302,"?*",'Гимнастические кольца и подвесы'!$L$3:$L$302,"<>Да") -> 4 | H8: =COUNTIFS('Гимнастические кольца и подвесы'!$E$3:$E$302,"?*",'Гимнастические кольца и подвесы'!$M$3:$M$302,"<>Да") -> 4 | I8: =COUNTIFS('Гимнастические кольца и подвесы'!$E$3:$E$302,"?*",'Гимнастические кольца и подвесы'!$AT$3:$AT$302,"") -> 0 | J8: =COUNTIFS('Гимнастические кольца и подвесы'!$E$3:$E$302,"?*",'Гимнастические кольца и подвесы'!$BB$3:$BB$302,"") -> 0 | K8: =SUM('Гимнастические кольца и подвесы'!$AK$3:$AK$302) -> 1550 | L8: =SUM('Гимнастические кольца и подвесы'!$BN$3:$BN$302) -> 1600 | M8: =SUM('Гимнастические кольца и подвесы'!$BO$3:$BO$302) -> 0 | N8: =SUMIF(ЗАКАЗЫ!$F$3:$F$500,"AKO-GK-*",ЗАКАЗЫ!$Y$3:$Y$500) -> 791400 | O8: =SUMIF(ЗАКАЗЫ!$F$3:$F$500,"AKO-GK-*",ЗАКАЗЫ!$AH$3:$AH$500) -> 4351000 | P8: =SUMIF(ЗАКАЗЫ!$F$3:$F$500,"AKO-GK-*",ЗАКАЗЫ!$AI$3:$AI$500) -> 3559600 | Q8: =IF(N(O8)=0,"",P8/O8) -> 0.81811078
A9: Комплектующие для качелей | B9: AKO-KK | C9: =COUNTIF('Комплектующие для качелей'!$E$3:$E$302,"?*") -> 9 | D9: =COUNTIF('Комплектующие для качелей'!$B$3:$B$302,"Готов к сайту") -> 0 | E9: =COUNTIF('Комплектующие для качелей'!$B$3:$B$302,"На сайте") -> 0 | F9: =COUNTIF('Комплектующие для качелей'!$D$3:$D$302,"Да") -> 0 | G9: =COUNTIFS('Комплектующие для качелей'!$E$3:$E$302,"?*",'Комплектующие для качелей'!$L$3:$L$302,"<>Да") -> 9 | H9: =COUNTIFS('Комплектующие для качелей'!$E$3:$E$302,"?*",'Комплектующие для качелей'!$M$3:$M$302,"<>Да") -> 9 | I9: =COUNTIFS('Комплектующие для качелей'!$E$3:$E$302,"?*",'Комплектующие для качелей'!$AT$3:$AT$302,"") -> 0 | J9: =COUNTIFS('Комплектующие для качелей'!$E$3:$E$302,"?*",'Комплектующие для качелей'!$BB$3:$BB$302,"") -> 0 | K9: =SUM('Комплектующие для качелей'!$AK$3:$AK$302) -> 1280 | L9: =SUM('Комплектующие для качелей'!$BN$3:$BN$302) -> 1280 | M9: =SUM('Комплектующие для качелей'!$BO$3:$BO$302) -> 0 | N9: =SUMIF(ЗАКАЗЫ!$F$3:$F$500,"AKO-KK-*",ЗАКАЗЫ!$Y$3:$Y$500) -> 25185710 | O9: =SUMIF(ЗАКАЗЫ!$F$3:$F$500,"AKO-KK-*",ЗАКАЗЫ!$AH$3:$AH$500) -> 60729310 | P9: =SUMIF(ЗАКАЗЫ!$F$3:$F$500,"AKO-KK-*",ЗАКАЗЫ!$AI$3:$AI$500) -> 35543600 | Q9: =IF(N(O9)=0,"",P9/O9) -> 0.58527917
A10: Зацепы скалодромные | B10: AKO-ZS | C10: =COUNTIF('Зацепы скалодромные'!$E$3:$E$302,"?*") -> 3 | D10: =COUNTIF('Зацепы скалодромные'!$B$3:$B$302,"Готов к сайту") -> 0 | E10: =COUNTIF('Зацепы скалодромные'!$B$3:$B$302,"На сайте") -> 0 | F10: =COUNTIF('Зацепы скалодромные'!$D$3:$D$302,"Да") -> 0 | G10: =COUNTIFS('Зацепы скалодромные'!$E$3:$E$302,"?*",'Зацепы скалодромные'!$L$3:$L$302,"<>Да") -> 3 | H10: =COUNTIFS('Зацепы скалодромные'!$E$3:$E$302,"?*",'Зацепы скалодромные'!$M$3:$M$302,"<>Да") -> 3 | I10: =COUNTIFS('Зацепы скалодромные'!$E$3:$E$302,"?*",'Зацепы скалодромные'!$AT$3:$AT$302,"") -> 0 | J10: =COUNTIFS('Зацепы скалодромные'!$E$3:$E$302,"?*",'Зацепы скалодромные'!$BB$3:$BB$302,"") -> 0 | K10: =SUM('Зацепы скалодромные'!$AK$3:$AK$302) -> 1400 | L10: =SUM('Зацепы скалодромные'!$BN$3:$BN$302) -> 1400 | M10: =SUM('Зацепы скалодромные'!$BO$3:$BO$302) -> 0 | N10: =SUMIF(ЗАКАЗЫ!$F$3:$F$500,"AKO-ZS-*",ЗАКАЗЫ!$Y$3:$Y$500) -> 936200 | O10: =SUMIF(ЗАКАЗЫ!$F$3:$F$500,"AKO-ZS-*",ЗАКАЗЫ!$AH$3:$AH$500) -> 2194200 | P10: =SUMIF(ЗАКАЗЫ!$F$3:$F$500,"AKO-ZS-*",ЗАКАЗЫ!$AI$3:$AI$500) -> 1258000 | Q10: =IF(N(O10)=0,"",P10/O10) -> 0.57332969
A11: Крепление для качелей | B11: AKO-KR | C11: =COUNTIF('Крепление для качелей'!$E$3:$E$302,"?*") -> 9 | D11: =COUNTIF('Крепление для качелей'!$B$3:$B$302,"Готов к сайту") -> 0 | E11: =COUNTIF('Крепление для качелей'!$B$3:$B$302,"На сайте") -> 0 | F11: =COUNTIF('Крепление для качелей'!$D$3:$D$302,"Да") -> 0 | G11: =COUNTIFS('Крепление для качелей'!$E$3:$E$302,"?*",'Крепление для качелей'!$L$3:$L$302,"<>Да") -> 9 | H11: =COUNTIFS('Крепление для качелей'!$E$3:$E$302,"?*",'Крепление для качелей'!$M$3:$M$302,"<>Да") -> 9 | I11: =COUNTIFS('Крепление для качелей'!$E$3:$E$302,"?*",'Крепление для качелей'!$AT$3:$AT$302,"") -> 0 | J11: =COUNTIFS('Крепление для качелей'!$E$3:$E$302,"?*",'Крепление для качелей'!$BB$3:$BB$302,"") -> 0 | K11: =SUM('Крепление для качелей'!$AK$3:$AK$302) -> 2420 | L11: =SUM('Крепление для качелей'!$BN$3:$BN$302) -> 2420 | M11: =SUM('Крепление для качелей'!$BO$3:$BO$302) -> 0 | N11: =SUMIF(ЗАКАЗЫ!$F$3:$F$500,"AKO-KR-*",ЗАКАЗЫ!$Y$3:$Y$500) -> 4373120 | O11: =SUMIF(ЗАКАЗЫ!$F$3:$F$500,"AKO-KR-*",ЗАКАЗЫ!$AH$3:$AH$500) -> 11458310 | P11: =SUMIF(ЗАКАЗЫ!$F$3:$F$500,"AKO-KR-*",ЗАКАЗЫ!$AI$3:$AI$500) -> 7085190 | Q11: =IF(N(O11)=0,"",P11/O11) -> 0.61834511
A12: Крепёж и такелаж | B12: AKO-KT | C12: =COUNTIF('Крепёж и такелаж'!$E$3:$E$302,"?*") -> 13 | D12: =COUNTIF('Крепёж и такелаж'!$B$3:$B$302,"Готов к сайту") -> 0 | E12: =COUNTIF('Крепёж и такелаж'!$B$3:$B$302,"На сайте") -> 0 | F12: =COUNTIF('Крепёж и такелаж'!$D$3:$D$302,"Да") -> 0 | G12: =COUNTIFS('Крепёж и такелаж'!$E$3:$E$302,"?*",'Крепёж и такелаж'!$L$3:$L$302,"<>Да") -> 13 | H12: =COUNTIFS('Крепёж и такелаж'!$E$3:$E$302,"?*",'Крепёж и такелаж'!$M$3:$M$302,"<>Да") -> 13 | I12: =COUNTIFS('Крепёж и такелаж'!$E$3:$E$302,"?*",'Крепёж и такелаж'!$AT$3:$AT$302,"") -> 0 | J12: =COUNTIFS('Крепёж и такелаж'!$E$3:$E$302,"?*",'Крепёж и такелаж'!$BB$3:$BB$302,"") -> 0 | K12: =SUM('Крепёж и такелаж'!$AK$3:$AK$302) -> 14950 | L12: =SUM('Крепёж и такелаж'!$BN$3:$BN$302) -> 14950 | M12: =SUM('Крепёж и такелаж'!$BO$3:$BO$302) -> 0 | N12: =SUMIF(ЗАКАЗЫ!$F$3:$F$500,"AKO-KT-*",ЗАКАЗЫ!$Y$3:$Y$500) -> 4778500 | O12: =SUMIF(ЗАКАЗЫ!$F$3:$F$500,"AKO-KT-*",ЗАКАЗЫ!$AH$3:$AH$500) -> 15891600 | P12: =SUMIF(ЗАКАЗЫ!$F$3:$F$500,"AKO-KT-*",ЗАКАЗЫ!$AI$3:$AI$500) -> 11113100 | Q12: =IF(N(O12)=0,"",P12/O12) -> 0.69930655
A13: ИТОГО | C13: =SUM(C5:C12) -> 72 | D13: =SUM(D5:D12) -> 1 | E13: =SUM(E5:E12) -> 1 | F13: =SUM(F5:F12) -> 1 | G13: =SUM(G5:G12) -> 72 | H13: =SUM(H5:H12) -> 72 | I13: =SUM(I5:I12) -> 0 | J13: =SUM(J5:J12) -> 0 | ... P13: =SUM(P5:P12) -> 93503690 | Q13: =IF(N(O13)=0,"",P13/O13) -> 0.61005619
A16: ЗАКАЗЫ
A17: ID заказа | B17: Поставщик | C17: Дата заказа | D17: Итого к оплате, ¥ | E17: Итого, ₸ | F17: Себестоимость партии, ₸ | G17: Выручка план, ₸ | H17: Прибыль план, ₸ | I17: Маржа, % | J17: Ожидаемый приход | K17: Пришло позиций | L17: Статус
A18: =IF('Сводка заказов'!A5="","",'Сводка заказов'!A5) -> SDN-1 | B18: =IF('Сводка заказов'!B5="","",'Сводка заказов'!B5) -> Ningbo Sidana | C18: =IF('Сводка заказов'!D5="","",'Сводка заказов'!D5) -> 46286 | D18: =IF('Сводка заказов'!K5="","",'Сводка заказов'!K5) -> 56285 | E18: =IF('Сводка заказов'!L5="","",'Сводка заказов'!L5) -> 3855523 | F18: =IF('Сводка заказов'!Y5="","",'Сводка заказов'!Y5) -> 4678620 | G18: =IF('Сводка заказов'!Z5="","",'Сводка заказов'!Z5) -> 12398480 | H18: =IF('Сводка заказов'!AA5="","",'Сводка заказов'!AA5) -> 7719860 | I18: =IF('Сводка заказов'!AB5="","",'Сводка заказов'!AB5) -> 0.62264568 | J18: =IF('Сводка заказов'!V5="","",'Сводка заказов'!V5) -> 46323 | K18: =IF('Сводка заказов'!AC5="","",'Сводка заказов'!AC5) -> 0 из 18 | L18: =IF('Сводка заказов'!AD5="","",'Сводка заказов'!AD5) -> Заказано
A19: =IF('Сводка заказов'!A6="","",'Сводка заказов'!A6) -> SDN-2-1 | B19: =IF('Сводка заказов'!B6="","",'Сводка заказов'!B6) -> Ningbo Sidana | C19: =IF('Сводка заказов'!D6="","",'Сводка заказов'!D6) -> 46309 | D19: =IF('Сводка заказов'!K6="","",'Сводка заказов'!K6) -> 143075 | E19: =IF('Сводка заказов'!L6="","",'Сводка заказов'!L6) -> 9800638 | F19: =IF('Сводка заказов'!Y6="","",'Сводка заказов'!Y6) -> 12062000 | G19: =IF('Сводка заказов'!Z6="","",'Сводка заказов'!Z6) -> 36043500 | H19: =IF('Сводка заказов'!AA6="","",'Сводка заказов'!AA6) -> 23981500 | I19: =IF('Сводка заказов'!AB6="","",'Сводка заказов'!AB6) -> 0.66534881 | J19: =IF('Сводка заказов'!V6="","",'Сводка заказов'!V6) -> 46346 | K19: =IF('Сводка заказов'!AC6="","",'Сводка заказов'!AC6) -> 0 из 27 | L19: =IF('Сводка заказов'!AD6="","",'Сводка заказов'!AD6) -> Заказано
A20: =IF('Сводка заказов'!A7="","",'Сводка заказов'!A7) -> SDN-2-2 | B20: =IF('Сводка заказов'!B7="","",'Сводка заказов'!B7) -> Ningbo Sidana | C20: =IF('Сводка заказов'!D7="","",'Сводка заказов'!D7) -> 46309 | D20: =IF('Сводка заказов'!K7="","",'Сводка заказов'!K7) -> 207190 | E20: =IF('Сводка заказов'!L7="","",'Сводка заказов'!L7) -> 14192515 | F20: =IF('Сводка заказов'!Y7="","",'Сводка заказов'!Y7) -> 17132500 | G20: =IF('Сводка заказов'!Z7="","",'Сводка заказов'!Z7) -> 46265500 | H20: =IF('Сводка заказов'!AA7="","",'Сводка заказов'!AA7) -> 29133000 | I20: =IF('Сводка заказов'!AB7="","",'Сводка заказов'!AB7) -> 0.62969167 | J20: =IF('Сводка заказов'!V7="","",'Сводка заказов'!V7) -> 46372 | K20: =IF('Сводка заказов'!AC7="","",'Сводка заказов'!AC7) -> 0 из 8 | L20: =IF('Сводка заказов'!AD7="","",'Сводка заказов'!AD7) -> Заказано
A21: =IF('Сводка заказов'!A8="","",'Сводка заказов'!A8) -> BS-1 | B21: =IF('Сводка заказов'!B8="","",'Сводка заказов'!B8) -> Ningbo Best Swing | C21: =IF('Сводка заказов'!D8="","",'Сводка заказов'!D8) | D21: =IF('Сводка заказов'!K8="","",'Сводка заказов'!K8) -> 274649 | E21: =IF('Сводка заказов'!L8="","",'Сводка заказов'!L8) -> 18813457 | F21: =IF('Сводка заказов'!Y8="","",'Сводка заказов'!Y8) -> 23047210 | G21: =IF('Сводка заказов'!Z8="","",'Сводка заказов'!Z8) -> 50499440 | H21: =IF('Сводка заказов'!AA8="","",'Сводка заказов'!AA8) -> 27452230 | I21: =IF('Сводка заказов'!AB8="","",'Сводка заказов'!AB8) -> 0.54361454 | J21: =IF('Сводка заказов'!V8="","",'Сводка заказов'!V8) | K21: =IF('Сводка заказов'!AC8="","",'Сводка заказов'!AC8) -> 0 из 18 | L21: =IF('Сводка заказов'!AD8="","",'Сводка заказов'!AD8) -> Заказано
A22: =IF('Сводка заказов'!A9="","",'Сводка заказов'!A9) -> QDF-1 | B22: =IF('Сводка заказов'!B9="","",'Сводка заказов'!B9) -> Qingdao Florescence | C22: =IF('Сводка заказов'!D9="","",'Сводка заказов'!D9) | D22: =IF('Сводка заказов'!K9="","",'Сводка заказов'!K9) -> 34194.5 | E22: =IF('Сводка заказов'!L9="","",'Сводка заказов'!L9) -> 2342323 | F22: =IF('Сводка заказов'!Y9="","",'Сводка заказов'!Y9) -> 2846600 | G22: =IF('Сводка заказов'!Z9="","",'Сводка заказов'!Z9) -> 8063700 | H22: =IF('Сводка заказов'!AA9="","",'Сводка заказов'!AA9) -> 5217100 | I22: =IF('Сводка заказов'!AB9="","",'Сводка заказов'!AB9) -> 0.64698587 | J22: =IF('Сводка заказов'!V9="","",'Сводка заказов'!V9) | K22: =IF('Сводка заказов'!AC9="","",'Сводка заказов'!AC9) -> 0 из 10 | L22: =IF('Сводка заказов'!AD9="","",'Сводка заказов'!AD9) -> Заказано
A23: ИТОГО | D23: ='Сводка заказов'!K25 -> 715393.5 | E23: ='Сводка заказов'!L25 -> 49004456 | F23: ='Сводка заказов'!Y25 -> 59766930 | G23: ='Сводка заказов'!Z25 -> 153270620 | H23: ='Сводка заказов'!AA25 -> 93503690 | I23: ='Сводка заказов'!AB25 -> 0.61005619
A25: Ставки пошлин и % логистики — допущения (см. листы «ТН ВЭД» и «Сводка заказов»). Цены «НАША» для новых товаров — автоцена серым курсивом, впиши свои.

Sheet Инструкция
A1: Как заполнять
A2: Жёлтые ячейки, синий текст — заполняешь ты.
A3: Серые ячейки — формулы, не трогай (имена фото, цены по порогам, себестоимость, маржа).
A4: Серая группа «Закупка» — только для нас, на сайт не выгружается.
A5: Артикулы AKO-XX-001… уже проставлены и закреплены за строками. Строки не удаляй — ненужный товар ставь в статус «Снят».
A6: ТОП = «Да» для 4–5 самых ходовых позиций категории (они пойдут на главную). Больше 5 — подсветится красным.
A7: Маржа ниже 20% подсвечивается красным.
A9: Цвета и количество
A10: У каждого товара 12 колонок-цветов (BLACK, ORANGE, RED, BLUE, GRAY…). Пишешь количество только в нужных цветах, пустые не трогаешь.
A11: Пример: канат AKO-KN-001 → BLACK 2000, ORANGE 2000, RED 2000, BLUE 2000, GRAY 2000. Итого (10 000) и список цветов посчитаются сами.
A12: Артикулы вариантов собираются автоматически: AKO-KN-001-BLACK, AKO-KN-001-ORANGE… — это готовые позиции для сайта и склада.
A13: Нужен новый цвет — переименуй COLOR-11 / COLOR-12 на листе «Справочники», заголовки обновятся на всех листах.
... A27: Пример заполненной строки (лист «ГИЛЬЗЫ И ВТУЛКИ»)
A28: Поле | B28: Пример
A29: Артикул AKO | B29: AKO-GV-001
A30: Статус | B30: Готов к сайту
A31: ТОП | B31: Да
A32: Название | B32: Гильза алюминиевая обжимная для каната 16 мм
A33: Подкатегория | B33: Гильзы обжимные
A34: Краткое описание | B34: Для обжима армированного каната Ø16 мм в узлах сеток и лазалок
A35: Материал | B35: Алюминий
A36: Цвет GRAY, шт | B36: 5000
A37: Цвет BLACK, шт | B37: 3000
A38: Под канат Ø, мм | B38: 16
A39: Наружный Ø, мм | B39: 24
A40: Внутренний Ø, мм | B40: 17
A41: Длина, мм | B41: 30
A42: Тип | B42: обжимная
A43: Вес, г | B43: 22
A44: Ед. изм. | B44: шт
A45: MOQ | B45: 500
A46: Цена zagluskha.ru, ₽ с НДС РФ | B46: 45
A47: НАША цена от MOQ, ₸ с НДС | B47: 260
A48: Поставщик | B48: Ningbo Best Swing
A49: Цена закупки | B49: 1.2
A50: Валюта | B50: CNY
A51: Срок изготовления, дн | B51: 20
A52: Цифры в примере условные — только чтобы показать формат.
A54: Заказы, себестоимость, склад (новое)
A55: «Сводка заказов» — одна строка на заказ: даты, оплата 30/70, % логистики, сроки, итог по партии. Новый заказ — впиши ID в первую пустую строку.
...

Sheet Сводка заказов
A1: Сводка заказов — оплаты, логистика, сроки, итог по себестоимости
A2: Жёлтое (синий текст) — заполняешь. Серое — формулы. % логистики, сроки и даты влияют на себестоимость и ожидаемую дату прихода всех позиций заказа на листе «ЗАКАЗЫ».
A3: Заказ | G3: Сумма | M3: Оплата | Q3: Логистика и сроки | W3: Итог по партии | AD3: Статус
A4: ID заказа | B4: Поставщик | C4: Договор / PO | D4: Дата заказа (договора) | E4: Дата оплаты аванса | F4: Условия поставки / оплаты | G4: Позиций | H4: Кол-во, шт / м | I4: Товар, ¥ | J4: Доп. расходы, ¥ (доставка, сэмплы) | K4: Итого к оплате, ¥ | L4: Итого, ₸ (по курсу) | M4: Аванс 30%, ¥ | N4: Аванс оплачен? | O4: Остаток 70%, ¥ | P4: Остаток оплачен? | Q4: Доп. расходы, % к товару | R4: Логистика до границы, % к закупке | S4: Логистика Хоргос → склад + брокер, % к закупке | T4: Срок производства, раб. дн | U4: Транзит до склада, дн | V4: Ожидаемый приход | W4: Пошлина, ₸ | X4: НДС при ввозе, ₸ | Y4: Себестоимость партии, ₸ | Z4: Выручка план (без НДС), ₸ | AA4: Прибыль план, ₸ | AB4: Маржа, % | AC4: Пришло позиций | AD4: Статус заказа | AE4: Комментарий
A5: SDN-1 | B5: Ningbo Sidana | C5: PO №1 · договор SDN260921 | D5: 46286 | F5: DPU Хоргос (склад Dituo), оплата 30% аванс / 70% после приёмки | G5: =IF($A5="","",COUNTIF(ЗАКАЗЫ!$A$3:$A$500,$A5)) -> 18 | H5: =IF($A5="","",SUMIF(ЗАКАЗЫ!$A$3:$A$500,$A5,ЗАКАЗЫ!$J$3:$J$500)) -> 6900 | I5: =IF($A5="","",SUMIF(ЗАКАЗЫ!$A$3:$A$500,$A5,ЗАКАЗЫ!$M$3:$M$500)) -> 56285 | J5: 0 | K5: =IF($A5="","",I5+N(J5)) -> 56285 | L5: =IF($A5="","",ROUND(K5*Справочники!$B$5,0)) -> 3855523 | M5: =IF($A5="","",ROUND(K5*0.3,2)) -> 16885.5 | N5: Нет | O5: =IF($A5="","",K5-M5) -> 39399.5 | P5: Нет | Q5: =IF(N(I5)=0,"",N(J5)/I5) -> 0 | R5: 0 | S5: 0.15 | T5: 12 | U5: 7 | V5: =IF(OR($A5="",T5="",AND(D5="",E5="")),"",WORKDAY(IF(E5<>"",E5,D5+14),T5)+N(U5)) -> 46323 | W5: =IF($A5="","",SUMIF(ЗАКАЗЫ!$A$3:$A$500,$A5,ЗАКАЗЫ!$Z$3:$Z$500)) -> 245166.7 | X5: =IF($A5="","",SUMIF(ЗАКАЗЫ!$A$3:$A$500,$A5,ЗАКАЗЫ!$AA$3:$AA$500)) -> 656104.5 | Y5: =IF($A5="","",SUMIF(ЗАКАЗЫ!$A$3:$A$500,$A5,ЗАКАЗЫ!$Y$3:$Y$500)) -> 4678620 | Z5: =IF($A5="","",SUMIF(ЗАКАЗЫ!$A$3:$A$500,$A5,ЗАКАЗЫ!$AH$3:$AH$500)) -> 12398480 | AA5: =IF($A5="","",SUMIF(ЗАКАЗЫ!$A$3:$A$500,$A5,ЗАКАЗЫ!$AI$3:$AI$500)) -> 7719860 | AB5: =IF(N(Z5)=0,"",AA5/Z5) -> 0.62264568 | AC5: =IF($A5="","",COUNTIFS(ЗАКАЗЫ!$A$3:$A$500,$A5,ЗАКАЗЫ!$AN$3:$AN$500,"Да")&" из "&G5) -> 0 из 18 | AD5: Заказано | AE5: В п. 4.1 договора сумма ¥51 485 (без каната №18), в Приложении 1 — ¥56 285. Уточнить у Sidana.
A6: SDN-2-1 | B6: Ningbo Sidana | C6: PO №2-1 · Standard (стоковые позиции) | D6: 46309 | F6: DPU Хоргос (склад Dituo), 30% аванс / 70% до отгрузки из Нинбо | G6: =IF($A6="","",COUNTIF(ЗАКАЗЫ!$A$3:$A$500,$A6)) -> 27 | H6: =IF($A6="","",SUMIF(ЗАКАЗЫ!$A$3:$A$500,$A6,ЗАКАЗЫ!$J$3:$J$500)) -> 55000 | I6: =IF($A6="","",SUMIF(ЗАКАЗЫ!$A$3:$A$500,$A6,ЗАКАЗЫ!$M$3:$M$500)) -> 143075 | J6: 0 | K6: =IF($A6="","",I6+N(J6)) -> 143075 | L6: =IF($A6="","",ROUND(K6*Справочники!$B$5,0)) -> 9800638 | M6: =IF($A6="","",ROUND(K6*0.3,2)) -> 42922.5 | N6: Нет | O6: =IF($A6="","",K6-M6) -> 100152.5 | P6: Нет | Q6: =IF(N(I6)=0,"",N(J6)/I6) -> 0 | R6: 0 | S6: 0.15 | T6: 12 | U6: 7 | V6: =IF(OR($A6="",T6="",AND(D6="",E6="")),"",WORKDAY(IF(E6<>"",E6,D6+14),T6)+N(U6)) -> 46346 | W6: =IF($A6="","",SUMIF(ЗАКАЗЫ!$A$3:$A$500,$A6,ЗАКАЗЫ!$Z$3:$Z$500)) -> 788300 | X6: =IF($A6="","",SUMIF(ЗАКАЗЫ!$A$3:$A$500,$A6,ЗАКАЗЫ!$AA$3:$AA$500)) -> 1694230 | Y6: =IF($A6="","",SUMIF(ЗАКАЗЫ!$A$3:$A$500,$A6,ЗАКАЗЫ!$Y$3:$Y$500)) -> 12062000 | Z6: =IF($A6="","",SUMIF(ЗАКАЗЫ!$A$3:$A$500,$A6,ЗАКАЗЫ!$AH$3:$AH$500)) -> 36043500 | AA6: =IF($A6="","",SUMIF(ЗАКАЗЫ!$A$3:$A$500,$A6,ЗАКАЗЫ!$AI$3:$AI$500)) -> 23981500 | AB6: =IF(N(Z6)=0,"",AA6/Z6) -> 0.66534881 | AC6: =IF($A6="","",COUNTIFS(ЗАКАЗЫ!$A$3:$A$500,$A6,ЗАКАЗЫ!$AN$3:$AN$500,"Да")&" из "&G6) -> 0 из 27 | AD6: Заказано | AE6: Дата в PO 2-1 не указана — взята по договору 2-2 (№2026101402 от 14.10.2026). Проверь.
A7: SDN-2-2 | B7: Ningbo Sidana | C7: PO №2-2 · Customized · договор №2026101402 | D7: 46309 | F7: DPU Хоргос, 30% аванс / 70% перед каждой отгрузкой. Отгрузка 1: поз. 1–7 + 100 гнёзд (30 раб. дн), отгрузка 2: 100 гнёзд (50 раб. дн) | G7: =IF($A7="","",COUNTIF(ЗАКАЗЫ!$A$3:$A$500,$A7)) -> 8 | H7: =IF($A7="","",SUMIF(ЗАКАЗЫ!$A$3:$A$500,$A7,ЗАКАЗЫ!$J$3:$J$500)) -> 11300 | I7: =IF($A7="","",SUMIF(ЗАКАЗЫ!$A$3:$A$500,$A7,ЗАКАЗЫ!$M$3:$M$500)) -> 207190 | J7: 0 | K7: =IF($A7="","",I7+N(J7)) -> 207190 | L7: =IF($A7="","",ROUND(K7*Справочники!$B$5,0)) -> 14192515 | M7: =IF($A7="","",ROUND(K7*0.3,2)) -> 62157 | N7: Нет | O7: =IF($A7="","",K7-M7) -> 145033 | P7: Нет | Q7: =IF(N(I7)=0,"",N(J7)/I7) -> 0 | R7: 0 | S7: 0.15 | T7: 30 | U7: 7 | V7: =IF(OR($A7="",T7="",AND(D7="",E7="")),"",WORKDAY(IF(E7<>"",E7,D7+14),T7)+N(U7)) -> 46372 | W7: =IF($A7="","",SUMIF(ЗАКАЗЫ!$A$3:$A$500,$A7,ЗАКАЗЫ!$Z$3:$Z$500)) -> 811547 | X7: =IF($A7="","",SUMIF(ЗАКАЗЫ!$A$3:$A$500,$A7,ЗАКАЗЫ!$AA$3:$AA$500)) -> 2400645 | Y7: =IF($A7="","",SUMIF(ЗАКАЗЫ!$A$3:$A$500,$A7,ЗАКАЗЫ!$Y$3:$Y$500)) -> 17132500 | Z7: =IF($A7="","",SUMIF(ЗАКАЗЫ!$A$3:$A$500,$A7,ЗАКАЗЫ!$AH$3:$AH$500)) -> 46265500 | AA7: =IF($A7="","",SUMIF(ЗАКАЗЫ!$A$3:$A$500,$A7,ЗАКАЗЫ!$AI$3:$AI$500)) -> 29133000 | AB7: =IF(N(Z7)=0,"",AA7/Z7) -> 0.62969167 | AC7: =IF($A7="","",COUNTIFS(ЗАКАЗЫ!$A$3:$A$500,$A7,ЗАКАЗЫ!$AN$3:$AN$500,"Да")&" из "&G7) -> 0 из 8 | AD7: Заказано | AE7: Перед производством Sidana присылает чертёж + фото образца каждой позиции на согласование (п. 3.4).
A8: BS-1 | B8: Ningbo Best Swing | C8: PO Best Swing (цены NEW) | F8: Условия поставки в PO не указаны | G8: =IF($A8="","",COUNTIF(ЗАКАЗЫ!$A$3:$A$500,$A8)) -> 18 | H8: =IF($A8="","",SUMIF(ЗАКАЗЫ!$A$3:$A$500,$A8,ЗАКАЗЫ!$J$3:$J$500)) -> 19000 | I8: =IF($A8="","",SUMIF(ЗАКАЗЫ!$A$3:$A$500,$A8,ЗАКАЗЫ!$M$3:$M$500)) -> 274649 | J8: 0 | K8: =IF($A8="","",I8+N(J8)) -> 274649 | L8: =IF($A8="","",ROUND(K8*Справочники!$B$5,0)) -> 18813457 | M8: =IF($A8="","",ROUND(K8*0.3,2)) -> 82394.7 | N8: Нет | O8: =IF($A8="","",K8-M8) -> 192254.3 | P8: Нет | Q8: =IF(N(I8)=0,"",N(J8)/I8) -> 0 | R8: 0 | S8: 0.15 | U8: 7 | V8: =IF(OR($A8="",T8="",AND(D8="",E8="")),"",WORKDAY(IF(E8<>"",E8,D8+14),T8)+N(U8)) | W8: =IF($A8="","",SUMIF(ЗАКАЗЫ!$A$3:$A$500,$A8,ЗАКАЗЫ!$Z$3:$Z$500)) -> 1412015.8 | X8: =IF($A8="","",SUMIF(ЗАКАЗЫ!$A$3:$A$500,$A8,ЗАКАЗЫ!$AA$3:$AA$500)) -> 3236109.6 | Y8: =IF($A8="","",SUMIF(ЗАКАЗЫ!$A$3:$A$500,$A8,ЗАКАЗЫ!$Y$3:$Y$500)) -> 23047210 | Z8: =IF($A8="","",SUMIF(ЗАКАЗЫ!$A$3:$A$500,$A8,ЗАКАЗЫ!$AH$3:$AH$500)) -> 50499440 | AA8: =IF($A8="","",SUMIF(ЗАКАЗЫ!$A$3:$A$500,$A8,ЗАКАЗЫ!$AI$3:$AI$500)) -> 27452230 | AB8: =IF(N(Z8)=0,"",AA8/Z8) -> 0.54361454 | AC8: =IF($A8="","",COUNTIFS(ЗАКАЗЫ!$A$3:$A$500,$A8,ЗАКАЗЫ!$AN$3:$AN$500,"Да")&" из "&G8) -> 0 из 18 | AD8: Заказано | AE8: Цены — колонка NEW PRICE. Дату заказа и условия поставки впиши. Если поставка не до Хоргоса — поставь % логистики до границы.
A9: QDF-1 | B9: Qingdao Florescence | C9: Договор поставки (Приложение 1), № и дата не заполнены | F9: DPU Хоргос (склад Dituo), 30% аванс / 70% до отгрузки | G9: =IF($A9="","",COUNTIF(ЗАКАЗЫ!$A$3:$A$500,$A9)) -> 10 | H9: =IF($A9="","",SUMIF(ЗАКАЗЫ!$A$3:$A$500,$A9,ЗАКАЗЫ!$J$3:$J$500)) -> 4050 | I9: =IF($A9="","",SUMIF(ЗАКАЗЫ!$A$3:$A$500,$A9,ЗАКАЗЫ!$M$3:$M$500)) -> 33025 | J9: 1169.5 | K9: =IF($A9="","",I9+N(J9)) -> 34194.5 | L9: =IF($A9="","",ROUND(K9*Справочники!$B$5,0)) -> 2342323 | M9: =IF($A9="","",ROUND(K9*0.3,2)) -> 10258.35 | N9: Нет | O9: =IF($A9="","",K9-M9) -> 23936.15 | P9: Нет | Q9: =IF(N(I9)=0,"",N(J9)/I9) -> 0.035412566 | R9: 0 | S9: 0.15 | U9: 7 | V9: =IF(OR($A9="",T9="",AND(D9="",E9="")),"",WORKDAY(IF(E9<>"",E9,D9+14),T9)+N(U9)) | W9: =IF($A9="","",SUMIF(ЗАКАЗЫ!$A$3:$A$500,$A9,ЗАКАЗЫ!$Z$3:$Z$500)) -> 164770 | X9: =IF($A9="","",SUMIF(ЗАКАЗЫ!$A$3:$A$500,$A9,ЗАКАЗЫ!$AA$3:$AA$500)) -> 401131 | Y9: =IF($A9="","",SUMIF(ЗАКАЗЫ!$A$3:$A$500,$A9,ЗАКАЗЫ!$Y$3:$Y$500)) -> 2846600 | Z9: =IF($A9="","",SUMIF(ЗАКАЗЫ!$A$3:$A$500,$A9,ЗАКАЗЫ!$AH$3:$AH$500)) -> 8063700 | AA9: =IF($A9="","",SUMIF(ЗАКАЗЫ!$A$3:$A$500,$A9,ЗАКАЗЫ!$AI$3:$AI$500)) -> 5217100 | AB9: =IF(N(Z9)=0,"",AA9/Z9) -> 0.64698587 | AC9: =IF($A9="","",COUNTIFS(ЗАКАЗЫ!$A$3:$A$500,$A9,ЗАКАЗЫ!$AN$3:$AN$500,"Да")&" из "&G9) -> 0 из 10 | AD9: Заказано | AE9: Доп. расходы ¥1 169,50 = доставка до Синьцзяна ¥1 000 + сэмплы ¥169,50 (3 позиции, в каталог не вносим). Итого по договору ¥34 194,50.
G10: =IF($A10="","",COUNTIF(ЗАКАЗЫ!$A$3:$A$500,$A10)) | H10: =IF($A10="","",SUMIF(ЗАКАЗЫ!$A$3:$A$500,$A10,ЗАКАЗЫ!$J$3:$J$500)) | I10: =IF($A10="","",SUMIF(ЗАКАЗЫ!$A$3:$A$500,$A10,ЗАКАЗЫ!$M$3:$M$500)) | K10: =IF($A10="","",I10+N(J10)) | L10: =IF($A10="","",ROUND(K10*Справочники!$B$5,0)) | M10: =IF($A10="","",ROUND(K10*0.3,2)) | O10: =IF($A10="","",K10-M10) | Q10: =IF(N(I10)=0,"",N(J10)/I10) | V10: =IF(OR($A10="",T10="",AND(D10="",E10="")),"",WORKDAY(IF(E10<>"",E10,D10+14),T10)+N(U10)) | W10: =IF($A10="","",SUMIF(ЗАКАЗЫ!$A$3:$A$500,$A10,ЗАКАЗЫ!$Z$3:$Z$500)) | X10: =IF($A10="","",SUMIF(ЗАКАЗЫ!$A$3:$A$500,$A10,ЗАКАЗЫ!$AA$3:$AA$500)) | Y10: =IF($A10="","",SUMIF(ЗАКАЗЫ!$A$3:$A$500,$A10,ЗАКАЗЫ!$Y$3:$Y$500)) | Z10: =IF($A10="","",SUMIF(ЗАКАЗЫ!$A$3:$A$500,$A10,ЗАКАЗЫ!$AH$3:$AH$500)) | AA10: =IF($A10="","",SUMIF(ЗАКАЗЫ!$A$3:$A$500,$A10,ЗАКАЗЫ!$AI$3:$AI$500)) | AB10: =IF(N(Z10)=0,"",AA10/Z10) | AC10: =IF($A10="","",COUNTIFS(ЗАКАЗЫ!$A$3:$A$500,$A10,ЗАКАЗЫ!$AN$3:$AN$500,"Да")&" из "&G10)
G11: =IF($A11="","",COUNTIF(ЗАКАЗЫ!$A$3:$A$500,$A11)) | H11: =IF($A11="","",SUMIF(ЗАКАЗЫ!$A$3:$A$500,$A11,ЗАКАЗЫ!$J$3:$J$500)) | I11: =IF($A11="","",SUMIF(ЗАКАЗЫ!$A$3:$A$500,$A11,ЗАКАЗЫ!$M$3:$M$500)) | K11: =IF($A11="","",I11+N(J11)) | L11: =IF($A11="","",ROUND(K11*Справочники!$B$5,0)) | M11: =IF($A11="","",ROUND(K11*0.3,2)) | O11: =IF($A11="","",K11-M11) | Q11: =IF(N(I11)=0,"",N(J11)/I11) | V11: =IF(OR($A11="",T11="",AND(D11="",E11="")),"",WORKDAY(IF(E11<>"",E11,D11+14),T11)+N(U11)) | W11: =IF($A11="","",SUMIF(ЗАКАЗЫ!$A$3:$A$500,$A11,ЗАКАЗЫ!$Z$3:$Z$500)) | X11: =IF($A11="","",SUMIF(ЗАКАЗЫ!$A$3:$A$500,$A11,ЗАКАЗЫ!$AA$3:$AA$500)) | Y11: =IF($A11="","",SUMIF(ЗАКАЗЫ!$A$3:$A$500,$A11,ЗАКАЗЫ!$Y$3:$Y$500)) | Z11: =IF($A11="","",SUMIF(ЗАКАЗЫ!$A$3:$A$500,$A11,ЗАКАЗЫ!$AH$3:$AH$500)) | AA11: =IF($A11="","",SUMIF(ЗАКАЗЫ!$A$3:$A$500,$A11,ЗАКАЗЫ!$AI$3:$AI$500)) | AB11: =IF(N(Z11)=0,"",AA11/Z11) | AC11: =IF($A11="","",COUNTIFS(ЗАКАЗЫ!$A$3:$A$500,$A11,ЗАКАЗЫ!$AN$3:$AN$500,"Да")&" из "&G11)
G12: =IF($A12="","",COUNTIF(ЗАКАЗЫ!$A$3:$A$500,$A12)) | H12: =IF($A12="","",SUMIF(ЗАКАЗЫ!$A$3:$A$500,$A12,ЗАКАЗЫ!$J$3:$J$500)) | I12: =IF($A12="","",SUMIF(ЗАКАЗЫ!$A$3:$A$500,$A12,ЗАКАЗЫ!$M$3:$M$500)) | K12: =IF($A12="","",I12+N(J12)) | L12: =IF($A12="","",ROUND(K12*Справочники!$B$5,0)) | M12: =IF($A12="","",ROUND(K12*0.3,2)) | O12: =IF($A12="","",K12-M12) | Q12: =IF(N(I12)=0,"",N(J12)/I12) | V12: =IF(OR($A12="",T12="",AND(D12="",E12="")),"",WORKDAY(IF(E12<>"",E12,D12+14),T12)+N(U12)) | W12: =IF($A12="","",SUMIF(ЗАКАЗЫ!$A$3:$A$500,$A12,ЗАКАЗЫ!$Z$3:$Z$500)) | X12: =IF($A12="","",SUMIF(ЗАКАЗЫ!$A$3:$A$500,$A12,ЗАКАЗЫ!$AA$3:$AA$500)) | Y12: =IF($A12="","",SUMIF(ЗАКАЗЫ!$A$3:$A$500,$A12,ЗАКАЗЫ!$Y$3:$Y$500)) | Z12: =IF($A12="","",SUMIF(ЗАКАЗЫ!$A$3:$A$500,$A12,ЗАКАЗЫ!$AH$3:$AH$500)) | AA12: =IF($A12="","",SUMIF(ЗАКАЗЫ!$A$3:$A$500,$A12,ЗАКАЗЫ!$AI$3:$AI$500)) | AB12: =IF(N(Z12)=0,"",AA12/Z12) | AC12: =IF($A12="","",COUNTIFS(ЗАКАЗЫ!$A$3:$A$500,$A12,ЗАКАЗЫ!$AN$3:$AN$500,"Да")&" из "&G12)
G13: =IF($A13="","",COUNTIF(ЗАКАЗЫ!$A$3:$A$500,$A13)) | H13: =IF($A13="","",SUMIF(ЗАКАЗЫ!$A$3:$A$500,$A13,ЗАКАЗЫ!$J$3:$J$500)) | I13: =IF($A13="","",SUMIF(ЗАКАЗЫ!$A$3:$A$500,$A13,ЗАКАЗЫ!$M$3:$M$500)) | K13: =IF($A13="","",I13+N(J13)) | L13: =IF($A13="","",ROUND(K13*Справочники!$B$5,0)) | M13: =IF($A13="","",ROUND(K13*0.3,2)) | O13: =IF($A13="","",K13-M13) | Q13: =IF(N(I13)=0,"",N(J13)/I13) | V13: =IF(OR($A13="",T13="",AND(D13="",E13="")),"",WORKDAY(IF(E13<>"",E13,D13+14),T13)+N(U13)) | W13: =IF($A13="","",SUMIF(ЗАКАЗЫ!$A$3:$A$500,$A13,ЗАКАЗЫ!$Z$3:$Z$500)) | X13: =IF($A13="","",SUMIF(ЗАКАЗЫ!$A$3:$A$500,$A13,ЗАКАЗЫ!$AA$3:$AA$500)) | Y13: =IF($A13="","",SUMIF(ЗАКАЗЫ!$A$3:$A$500,$A13,ЗАКАЗЫ!$Y$3:$Y$500)) | Z13: =IF($A13="","",SUMIF(ЗАКАЗЫ!$A$3:$A$500,$A13,ЗАКАЗЫ!$AH$3:$AH$500)) | AA13: =IF($A13="","",SUMIF(ЗАКАЗЫ!$A$3:$A$500,$A13,ЗАКАЗЫ!$AI$3:$AI$500)) | AB13: =IF(N(Z13)=0,"",AA13/Z13) | AC13: =IF($A13="","",COUNTIFS(ЗАКАЗЫ!$A$3:$A$500,$A13,ЗАКАЗЫ!$AN$3:$AN$500,"Да")&" из "&G13)
G14: =IF($A14="","",COUNTIF(ЗАКАЗЫ!$A$3:$A$500,$A14)) | H14: =IF($A14="","",SUMIF(ЗАКАЗЫ!$A$3:$A$500,$A14,ЗАКАЗЫ!$J$3:$J$500)) | I14: =IF($A14="","",SUMIF(ЗАКАЗЫ!$A$3:$A$500,$A14,ЗАКАЗЫ!$M$3:$M$500)) | K14: =IF($A14="","",I14+N(J14)) | L14: =IF($A14="","",ROUND(K14*Справочники!$B$5,0)) | M14: =IF($A14="","",ROUND(K14*0.3,2)) | O14: =IF($A14="","",K14-M14) | Q14: =IF(N(I14)=0,"",N(J14)/I14) | V14: =IF(OR($A14="",T14="",AND(D14="",E14="")),"",WORKDAY(IF(E14<>"",E14,D14+14),T14)+N(U14)) | W14: =IF($A14="","",SUMIF(ЗАКАЗЫ!$A$3:$A$500,$A14,ЗАКАЗЫ!$Z$3:$Z$500)) | X14: =IF($A14="","",SUMIF(ЗАКАЗЫ!$A$3:$A$500,$A14,ЗАКАЗЫ!$AA$3:$AA$500)) | Y14: =IF($A14="","",SUMIF(ЗАКАЗЫ!$A$3:$A$500,$A14,ЗАКАЗЫ!$Y$3:$Y$500)) | Z14: =IF($A14="","",SUMIF(ЗАКАЗЫ!$A$3:$A$500,$A14,ЗАКАЗЫ!$AH$3:$AH$500)) | AA14: =IF($A14="","",SUMIF(ЗАКАЗЫ!$A$3:$A$500,$A14,ЗАКАЗЫ!$AI$3:$AI$500)) | AB14: =IF(N(Z14)=0,"",AA14/Z14) | AC14: =IF($A14="","",COUNTIFS(ЗАКАЗЫ!$A$3:$A$500,$A14,ЗАКАЗЫ!$AN$3:$AN$500,"Да")&" из "&G14)
G15: =IF($A15="","",COUNTIF(ЗАКАЗЫ!$A$3:$A$500,$A15)) | H15: =IF($A15="","",SUMIF(ЗАКАЗЫ!$A$3:$A$500,$A15,ЗАКАЗЫ!$J$3:$J$500)) | I15: =IF($A15="","",SUMIF(ЗАКАЗЫ!$A$3:$A$500,$A15,ЗАКАЗЫ!$M$3:$M$500)) | K15: =IF($A15="","",I15+N(J15)) | L15: =IF($A15="","",ROUND(K15*Справочники!$B$5,0)) | M15: =IF($A15="","",ROUND(K15*0.3,2)) | O15: =IF($A15="","",K15-M15) | Q15: =IF(N(I15)=0,"",N(J15)/I15) | V15: =IF(OR($A15="",T15="",AND(D15="",E15="")),"",WORKDAY(IF(E15<>"",E15,D15+14),T15)+N(U15)) | W15: =IF($A15="","",SUMIF(ЗАКАЗЫ!$A$3:$A$500,$A15,ЗАКАЗЫ!$Z$3:$Z$500)) | X15: =IF($A15="","",SUMIF(ЗАКАЗЫ!$A$3:$A$500,$A15,ЗАКАЗЫ!$AA$3:$AA$500)) | Y15: =IF($A15="","",SUMIF(ЗАКАЗЫ!$A$3:$A$500,$A15,ЗАКАЗЫ!$Y$3:$Y$500)) | Z15: =IF($A15="","",SUMIF(ЗАКАЗЫ!$A$3:$A$500,$A15,ЗАКАЗЫ!$AH$3:$AH$500)) | AA15: =IF($A15="","",SUMIF(ЗАКАЗЫ!$A$3:$A$500,$A15,ЗАКАЗЫ!$AI$3:$AI$500)) | AB15: =IF(N(Z15)=0,"",AA15/Z15) | AC15: =IF($A15="","",COUNTIFS(ЗАКАЗЫ!$A$3:$A$500,$A15,ЗАКАЗЫ!$AN$3:$AN$500,"Да")&" из "&G15)
G16: =IF($A16="","",COUNTIF(ЗАКАЗЫ!$A$3:$A$500,$A16)) | H16: =IF($A16="","",SUMIF(ЗАКАЗЫ!$A$3:$A$500,$A16,ЗАКАЗЫ!$J$3:$J$500)) | I16: =IF($A16="","",SUMIF(ЗАКАЗЫ!$A$3:$A$500,$A16,ЗАКАЗЫ!$M$3:$M$500)) | K16: =IF($A16="","",I16+N(J16)) | L16: =IF($A16="","",ROUND(K16*Справочники!$B$5,0)) | M16: =IF($A16="","",ROUND(K16*0.3,2)) | O16: =IF($A16="","",K16-M16) | Q16: =IF(N(I16)=0,"",N(J16)/I16) | V16: =IF(OR($A16="",T16="",AND(D16="",E16="")),"",WORKDAY(IF(E16<>"",E16,D16+14),T16)+N(U16)) | W16: =IF($A16="","",SUMIF(ЗАКАЗЫ!$A$3:$A$500,$A16,ЗАКАЗЫ!$Z$3:$Z$500)) | X16: =IF($A16="","",SUMIF(ЗАКАЗЫ!$A$3:$A$500,$A16,ЗАКАЗЫ!$AA$3:$AA$500)) | Y16: =IF($A16="","",SUMIF(ЗАКАЗЫ!$A$3:$A$500,$A16,ЗАКАЗЫ!$Y$3:$Y$500)) | Z16: =IF($A16="","",SUMIF(ЗАКАЗЫ!$A$3:$A$500,$A16,ЗАКАЗЫ!$AH$3:$AH$500)) | AA16: =IF($A16="","",SUMIF(ЗАКАЗЫ!$A$3:$A$500,$A16,ЗАКАЗЫ!$AI$3:$AI$500)) | AB16: =IF(N(Z16)=0,"",AA16/Z16) | AC16: =IF($A16="","",COUNTIFS(ЗАКАЗЫ!$A$3:$A$500,$A16,ЗАКАЗЫ!$AN$3:$AN$500,"Да")&" из "&G16)
G17: =IF($A17="","",COUNTIF(ЗАКАЗЫ!$A$3:$A$500,$A17)) | H17: =IF($A17="","",SUMIF(ЗАКАЗЫ!$A$3:$A$500,$A17,ЗАКАЗЫ!$J$3:$J$500)) | I17: =IF($A17="","",SUMIF(ЗАКАЗЫ!$A$3:$A$500,$A17,ЗАКАЗЫ!$M$3:$M$500)) | K17: =IF($A17="","",I17+N(J17)) | L17: =IF($A17="","",ROUND(K17*Справочники!$B$5,0)) | M17: =IF($A17="","",ROUND(K17*0.3,2)) | O17: =IF($A17="","",K17-M17) | Q17: =IF(N(I17)=0,"",N(J17)/I17) | V17: =IF(OR($A17="",T17="",AND(D17="",E17="")),"",WORKDAY(IF(E17<>"",E17,D17+14),T17)+N(U17)) | W17: =IF($A17="","",SUMIF(ЗАКАЗЫ!$A$3:$A$500,$A17,ЗАКАЗЫ!$Z$3:$Z$500)) | X17: =IF($A17="","",SUMIF(ЗАКАЗЫ!$A$3:$A$500,$A17,ЗАКАЗЫ!$AA$3:$AA$500)) | Y17: =IF($A17="","",SUMIF(ЗАКАЗЫ!$A$3:$A$500,$A17,ЗАКАЗЫ!$Y$3:$Y$500)) | Z17: =IF($A17="","",SUMIF(ЗАКАЗЫ!$A$3:$A$500,$A17,ЗАКАЗЫ!$AH$3:$AH$500)) | AA17: =IF($A17="","",SUMIF(ЗАКАЗЫ!$A$3:$A$500,$A17,ЗАКАЗЫ!$AI$3:$AI$500)) | AB17: =IF(N(Z17)=0,"",AA17/Z17) | AC17: =IF($A17="","",COUNTIFS(ЗАКАЗЫ!$A$3:$A$500,$A17,ЗАКАЗЫ!$AN$3:$AN$500,"Да")&" из "&G17)
G18: =IF($A18="","",COUNTIF(ЗАКАЗЫ!$A$3:$A$500,$A18)) | H18: =IF($A18="","",SUMIF(ЗАКАЗЫ!$A$3:$A$500,$A18,ЗАКАЗЫ!$J$3:$J$500)) | I18: =IF($A18="","",SUMIF(ЗАКАЗЫ!$A$3:$A$500,$A18,ЗАКАЗЫ!$M$3:$M$500)) | K18: =IF($A18="","",I18+N(J18)) | L18: =IF($A18="","",ROUND(K18*Справочники!$B$5,0)) | M18: =IF($A18="","",ROUND(K18*0.3,2)) | O18: =IF($A18="","",K18-M18) | Q18: =IF(N(I18)=0,"",N(J18)/I18) | V18: =IF(OR($A18="",T18="",AND(D18="",E18="")),"",WORKDAY(IF(E18<>"",E18,D18+14),T18)+N(U18)) | W18: =IF($A18="","",SUMIF(ЗАКАЗЫ!$A$3:$A$500,$A18,ЗАКАЗЫ!$Z$3:$Z$500)) | X18: =IF($A18="","",SUMIF(ЗАКАЗЫ!$A$3:$A$500,$A18,ЗАКАЗЫ!$AA$3:$AA$500)) | Y18: =IF($A18="","",SUMIF(ЗАКАЗЫ!$A$3:$A$500,$A18,ЗАКАЗЫ!$Y$3:$Y$500)) | Z18: =IF($A18="","",SUMIF(ЗАКАЗЫ!$A$3:$A$500,$A18,ЗАКАЗЫ!$AH$3:$AH$500)) | AA18: =IF($A18="","",SUMIF(ЗАКАЗЫ!$A$3:$A$500,$A18,ЗАКАЗЫ!$AI$3:$AI$500)) | AB18: =IF(N(Z18)=0,"",AA18/Z18) | AC18: =IF($A18="","",COUNTIFS(ЗАКАЗЫ!$A$3:$A$500,$A18,ЗАКАЗЫ!$AN$3:$AN$500,"Да")&" из "&G18)
G19: =IF($A19="","",COUNTIF(ЗАКАЗЫ!$A$3:$A$500,$A19)) | H19: =IF($A19="","",SUMIF(ЗАКАЗЫ!$A$3:$A$500,$A19,ЗАКАЗЫ!$J$3:$J$500)) | I19: =IF($A19="","",SUMIF(ЗАКАЗЫ!$A$3:$A$500,$A19,ЗАКАЗЫ!$M$3:$M$500)) | K19: =IF($A19="","",I19+N(J19)) | L19: =IF($A19="","",ROUND(K19*Справочники!$B$5,0)) | M19: =IF($A19="","",ROUND(K19*0.3,2)) | O19: =IF($A19="","",K19-M19) | Q19: =IF(N(I19)=0,"",N(J19)/I19) | V19: =IF(OR($A19="",T19="",AND(D19="",E19="")),"",WORKDAY(IF(E19<>"",E19,D19+14),T19)+N(U19)) | W19: =IF($A19="","",SUMIF(ЗАКАЗЫ!$A$3:$A$500,$A19,ЗАКАЗЫ!$Z$3:$Z$500)) | X19: =IF($A19="","",SUMIF(ЗАКАЗЫ!$A$3:$A$500,$A19,ЗАКАЗЫ!$AA$3:$AA$500)) | Y19: =IF($A19="","",SUMIF(ЗАКАЗЫ!$A$3:$A$500,$A19,ЗАКАЗЫ!$Y$3:$Y$500)) | Z19: =IF($A19="","",SUMIF(ЗАКАЗЫ!$A$3:$A$500,$A19,ЗАКАЗЫ!$AH$3:$AH$500)) | AA19: =IF($A19="","",SUMIF(ЗАКАЗЫ!$A$3:$A$500,$A19,ЗАКАЗЫ!$AI$3:$AI$500)) | AB19: =IF(N(Z19)=0,"",AA19/Z19) | AC19: =IF($A19="","",COUNTIFS(ЗАКАЗЫ!$A$3:$A$500,$A19,ЗАКАЗЫ!$AN$3:$AN$500,"Да")&" из "&G19)
G20: =IF($A20="","",COUNTIF(ЗАКАЗЫ!$A$3:$A$500,$A20)) | H20: =IF($A20="","",SUMIF(ЗАКАЗЫ!$A$3:$A$500,$A20,ЗАКАЗЫ!$J$3:$J$500)) | I20: =IF($A20="","",SUMIF(ЗАКАЗЫ!$A$3:$A$500,$A20,ЗАКАЗЫ!$M$3:$M$500)) | K20: =IF($A20="","",I20+N(J20)) | L20: =IF($A20="","",ROUND(K20*Справочники!$B$5,0)) | M20: =IF($A20="","",ROUND(K20*0.3,2)) | O20: =IF($A20="","",K20-M20) | Q20: =IF(N(I20)=0,"",N(J20)/I20) | V20: =IF(OR($A20="",T20="",AND(D20="",E20="")),"",WORKDAY(IF(E20<>"",E20,D20+14),T20)+N(U20)) | W20: =IF($A20="","",SUMIF(ЗАКАЗЫ!$A$3:$A$500,$A20,ЗАКАЗЫ!$Z$3:$Z$500)) | X20: =IF($A20="","",SUMIF(ЗАКАЗЫ!$A$3:$A$500,$A20,ЗАКАЗЫ!$AA$3:$AA$500)) | Y20: =IF($A20="","",SUMIF(ЗАКАЗЫ!$A$3:$A$500,$A20,ЗАКАЗЫ!$Y$3:$Y$500)) | Z20: =IF($A20="","",SUMIF(ЗАКАЗЫ!$A$3:$A$500,$A20,ЗАКАЗЫ!$AH$3:$AH$500)) | AA20: =IF($A20="","",SUMIF(ЗАКАЗЫ!$A$3:$A$500,$A20,ЗАКАЗЫ!$AI$3:$AI$500)) | AB20: =IF(N(Z20)=0,"",AA20/Z20) | AC20: =IF($A20="","",COUNTIFS(ЗАКАЗЫ!$A$3:$A$500,$A20,ЗАКАЗЫ!$AN$3:$AN$500,"Да")&" из "&G20)
G21: =IF($A21="","",COUNTIF(ЗАКАЗЫ!$A$3:$A$500,$A21)) | H21: =IF($A21="","",SUMIF(ЗАКАЗЫ!$A$3:$A$500,$A21,ЗАКАЗЫ!$J$3:$J$500)) | I21: =IF($A21="","",SUMIF(ЗАКАЗЫ!$A$3:$A$500,$A21,ЗАКАЗЫ!$M$3:$M$500)) | K21: =IF($A21="","",I21+N(J21)) | L21: =IF($A21="","",ROUND(K21*Справочники!$B$5,0)) | M21: =IF($A21="","",ROUND(K21*0.3,2)) | O21: =IF($A21="","",K21-M21) | Q21: =IF(N(I21)=0,"",N(J21)/I21) | V21: =IF(OR($A21="",T21="",AND(D21="",E21="")),"",WORKDAY(IF(E21<>"",E21,D21+14),T21)+N(U21)) | W21: =IF($A21="","",SUMIF(ЗАКАЗЫ!$A$3:$A$500,$A21,ЗАКАЗЫ!$Z$3:$Z$500)) | X21: =IF($A21="","",SUMIF(ЗАКАЗЫ!$A$3:$A$500,$A21,ЗАКАЗЫ!$AA$3:$AA$500)) | Y21: =IF($A21="","",SUMIF(ЗАКАЗЫ!$A$3:$A$500,$A21,ЗАКАЗЫ!$Y$3:$Y$500)) | Z21: =IF($A21="","",SUMIF(ЗАКАЗЫ!$A$3:$A$500,$A21,ЗАКАЗЫ!$AH$3:$AH$500)) | AA21: =IF($A21="","",SUMIF(ЗАКАЗЫ!$A$3:$A$500,$A21,ЗАКАЗЫ!$AI$3:$AI$500)) | AB21: =IF(N(Z21)=0,"",AA21/Z21) | AC21: =IF($A21="","",COUNTIFS(ЗАКАЗЫ!$A$3:$A$500,$A21,ЗАКАЗЫ!$AN$3:$AN$500,"Да")&" из "&G21)
... G24: =IF($A24="","",COUNTIF(ЗАКАЗЫ!$A$3:$A$500,$A24)) | H24: =IF($A24="","",SUMIF(ЗАКАЗЫ!$A$3:$A$500,$A24,ЗАКАЗЫ!$J$3:$J$500)) | I24: =IF($A24="","",SUMIF(ЗАКАЗЫ!$A$3:$A$500,$A24,ЗАКАЗЫ!$M$3:$M$500)) | K24: =IF($A24="","",I24+N(J24)) | L24: =IF($A24="","",ROUND(K24*Справочники!$B$5,0)) | M24: =IF($A24="","",ROUND(K24*0.3,2)) | O24: =IF($A24="","",K24-M24) | Q24: =IF(N(I24)=0,"",N(J24)/I24) | V24: =IF(OR($A24="",T24="",AND(D24="",E24="")),"",WORKDAY(IF(E24<>"",E24,D24+14),T24)+N(U24)) | W24: =IF($A24="","",SUMIF(ЗАКАЗЫ!$A$3:$A$500,$A24,ЗАКАЗЫ!$Z$3:$Z$500)) | X24: =IF($A24="","",SUMIF(ЗАКАЗЫ!$A$3:$A$500,$A24,ЗАКАЗЫ!$AA$3:$AA$500)) | Y24: =IF($A24="","",SUMIF(ЗАКАЗЫ!$A$3:$A$500,$A24,ЗАКАЗЫ!$Y$3:$Y$500)) | Z24: =IF($A24="","",SUMIF(ЗАКАЗЫ!$A$3:$A$500,$A24,ЗАКАЗЫ!$AH$3:$AH$500)) | AA24: =IF($A24="","",SUMIF(ЗАКАЗЫ!$A$3:$A$500,$A24,ЗАКАЗЫ!$AI$3:$AI$500)) | AB24: =IF(N(Z24)=0,"",AA24/Z24) | AC24: =IF($A24="","",COUNTIFS(ЗАКАЗЫ!$A$3:$A$500,$A24,ЗАКАЗЫ!$AN$3:$AN$500,"Да")&" из "&G24)
A25: ИТОГО | G25: =SUM(G5:G24) -> 81 | H25: =SUM(H5:H24) -> 96250 | I25: =SUM(I5:I24) -> 714224 | J25: =SUM(J5:J24) -> 1169.5 | K25: =SUM(K5:K24) -> 715393.5 | L25: =SUM(L5:L24) -> 49004456 | M25: =SUM(M5:M24) -> 214618.05 | O25: =SUM(O5:O24) -> 500775.45 | W25: =SUM(W5:W24) -> 3421799.5 | X25: =SUM(X5:X24) -> 8388220.1 | Y25: =SUM(Y5:Y24) -> 59766930 | Z25: =SUM(Z5:Z24) -> 153270620 | AA25: =SUM(AA5:AA24) -> 93503690 | AB25: =IF(N(Z25)=0,"",AA25/Z25) -> 0.61005619
A28: Сэмплы Qingdao Florescence (QDF-1, поз. 11–13) — только для проверки, в каталог не вносим
A29: № в договоре | B29: Описание | C29: Кол-во (≈ сумма / цена) | D29: Цена, ¥ | E29: Сумма, ¥
A30: 11 | B30: For 16mm rope (сэмпл) | C30: 9 | D30: 3.3 | E30: 29.97
A31: 12 | B31: Ropes accessories (сэмпл) | C31: 30 | D31: 3.651 | E31: 109.53
A32: 13 | B32: For 16mm rope (сэмпл) | C32: 12 | D32: 2.5 | E32: 30
D33: Итого | E33: =SUM(E30:E32) -> 169.5
A34: Сумма сэмплов + доставка ¥1 000 вписаны в «Доп. расходы» QDF-1 и разнесены на позиции пропорционально сумме.

Sheet ЗАКАЗЫ
A1: Заказ | F1: Товар и закупка | N1: Таможня | Q1: Себестоимость (за единицу и за партию) | AB1: Продажа и маржа | AJ1: Поставка и склад
A2: ID заказа | B2: Поставщик | C2: Дата заказа | D2: № в заказе | E2: ФОТО | F2: Артикул AKO | G2: Название (из каталога) | H2: Название у поставщика | I2: Цвета / раскладка | J2: Кол-во | K2: Ед. | L2: Цена, ¥ | M2: Сумма, ¥ | N2: Код ТН ВЭД | O2: Пошлина, % | P2: НДС ввоз, % | Q2: Закупка, ₸/ед | R2: Доп. расходы заказа, ₸/ед | S2: Логистика до границы, ₸/ед | T2: Таможенная стоимость, ₸/ед | U2: Пошлина, ₸/ед | V2: НДС при ввозе, ₸/ед | W2: Логистика до склада + брокер, ₸/ед | X2: СЕБЕСТОИМОСТЬ, ₸/ед | Y2: Себестоимость партии, ₸ | Z2: Пошлина за партию, ₸ | AA2: НДС ввоз за партию, ₸ | AB2: zagluskha.ru, ₽ | AC2: zagluskha, ₸ с НДС РК | AD2: НАША цена, ₸ с НДС | AE2: НАША цена, ₸ без НДС | AF2: Маржа, ₸/ед | AG2: Маржа, % | AH2: Выручка план (без НДС), ₸ | AI2: Прибыль план, ₸ | AJ2: Статус поставки | AK2: Ожидаемый приход | AL2: Пришло на склад, шт | AM2: Дата прихода | AN2: Пришло? | AO2: Осталось прийти | AP2: Комментарий
A3: SDN-1 | B3: =IFERROR(INDEX('Сводка заказов'!$B$5:$B$24,MATCH($A3,'Сводка заказов'!$A$5:$A$24,0)),"") -> Ningbo Sidana | C3: =IFERROR(IF(INDEX('Сводка заказов'!$D$5:$D$24,MATCH($A3,'Сводка заказов'!$A$5:$A$24,0))="","",INDEX('Сводка заказов'!$D$5:$D$24,MATCH($A3,'Сводка заказов'!$A$5:$A$24,0))),"") -> 46286 | D3: 1 | F3: AKO-KK-003 | G3: ='Комплектующие для качелей'!$E$5 -> Качели «Гнездо» Ø1000 мм с подвесами, нагрузка до 250 кг | H3: Round Mid-range Swing φ100 cm | I3: по фото: красная сетка, синяя рама | J3: 30 | K3: шт | L3: 850 | M3: =J3*L3 -> 25500 | N3: 9506 99 900 0 | O3: =IFERROR(VLOOKUP($N3,'ТН ВЭД'!$A$4:$C$40,3,0),0) -> 0.05 | P3: =Справочники!$B$12 -> 0.16 | Q3: =ROUND(L3*Справочники!$B$5,2) -> 58225 | R3: =ROUND(Q3*N(IFERROR(INDEX('Сводка заказов'!$Q$5:$Q$24,MATCH($A3,'Сводка заказов'!$A$5:$A$24,0)),0)),2) -> 0 | S3: =ROUND(Q3*N(IFERROR(INDEX('Сводка заказов'!$R$5:$R$24,MATCH($A3,'Сводка заказов'!$A$5:$A$24,0)),0)),2) -> 0 | T3: =Q3+R3+S3 -> 58225 | U3: =ROUND(T3*O3,2) -> 2911.25 | V3: =ROUND((T3+U3)*P3,2) -> 9781.8 | W3: =ROUND(Q3*N(IFERROR(INDEX('Сводка заказов'!$S$5:$S$24,MATCH($A3,'Сводка заказов'!$A$5:$A$24,0)),0)),2) -> 8733.75 | X3: =ROUND(T3+U3+W3+IF(Справочники!$B$22="Да",0,V3),0) -> 69870 | Y3: =X3*J3 -> 2096100 | Z3: =U3*J3 -> 87337.5 | AA3: =V3*J3 -> 293454 | AB3: =IF('Комплектующие для качелей'!$AO$5="","",'Комплектующие для качелей'!$AO$5) -> 39000 | AC3: =IF('Комплектующие для качелей'!$AR$5="","",'Комплектующие для качелей'!$AR$5) -> 239772 | AD3: =IF('Комплектующие для качелей'!$AT$5="","",'Комплектующие для качелей'!$AT$5) -> 220590 | AE3: =IF(AD3="","",ROUND(AD3/(1+P3),0)) -> 190164 | AF3: =IF(AE3="","",AE3-X3) -> 120294 | AG3: =IF(OR(AE3="",AE3=0),"",AF3/AE3) -> 0.6325803 | AH3: =IF(AE3="",0,AE3*J3) -> 5704920 | AI3: =IF(AF3="",0,AF3*J3) -> 3608820 | AJ3: Заказано | AK3: =IFERROR(IF(INDEX('Сводка заказов'!$V$5:$V$24,MATCH($A3,'Сводка заказов'!$A$5:$A$24,0))="","",INDEX('Сводка заказов'!$V$5:$V$24,MATCH($A3,'Сводка заказов'!$A$5:$A$24,0))),"") -> 46323 | AN3: =IF(N(AL3)=0,"Нет",IF(AL3>=J3,"Да","Частично")) -> Нет | AO3: =J3-N(AL3) -> 30 | AP3: Цвет в договоре не указан — уточнить у Sidana
A4: SDN-1 | B4: =IFERROR(INDEX('Сводка заказов'!$B$5:$B$24,MATCH($A4,'Сводка заказов'!$A$5:$A$24,0)),"") -> Ningbo Sidana | C4: =IFERROR(IF(INDEX('Сводка заказов'!$D$5:$D$24,MATCH($A4,'Сводка заказов'!$A$5:$A$24,0))="","",INDEX('Сводка заказов'!$D$5:$D$24,MATCH($A4,'Сводка заказов'!$A$5:$A$24,0))),"") -> 46286 | D4: 2 | F4: AKO-KR-001 | G4: ='Крепление для качелей'!$E$3 -> Крепление для качелей из нержавеющей стали, пластина 90 мм | H4: Swing Fixing Buckle (stainless) | I4: — | J4: 10 | K4: шт | L4: 33 | M4: =J4*L4 -> 330 | N4: 7326 90 980 7 | O4: =IFERROR(VLOOKUP($N4,'ТН ВЭД'!$A$4:$C$40,3,0),0) -> 0.075 | P4: =Справочники!$B$12 -> 0.16 | Q4: =ROUND(L4*Справочники!$B$5,2) -> 2260.5 | R4: =ROUND(Q4*N(IFERROR(INDEX('Сводка заказов'!$Q$5:$Q$24,MATCH($A4,'Сводка заказов'!$A$5:$A$24,0)),0)),2) -> 0 | S4: =ROUND(Q4*N(IFERROR(INDEX('Сводка заказов'!$R$5:$R$24,MATCH($A4,'Сводка заказов'!$A$5:$A$24,0)),0)),2) -> 0 | T4: =Q4+R4+S4 -> 2260.5 | U4: =ROUND(T4*O4,2) -> 169.54 | V4: =ROUND((T4+U4)*P4,2) -> 388.81 | W4: =ROUND(Q4*N(IFERROR(INDEX('Сводка заказов'!$S$5:$S$24,MATCH($A4,'Сводка заказов'!$A$5:$A$24,0)),0)),2) -> 339.08 | X4: =ROUND(T4+U4+W4+IF(Справочники!$B$22="Да",0,V4),0) -> 2769 | Y4: =X4*J4 -> 27690 | Z4: =U4*J4 -> 1695.4 | AA4: =V4*J4 -> 3888.1 | AB4: =IF('Крепление для качелей'!$AO$3="","",'Крепление для качелей'!$AO$3) | AC4: =IF('Крепление для качелей'!$AR$3="","",'Крепление для качелей'!$AR$3) | AD4: =IF('Крепление для качелей'!$AT$3="","",'Крепление для качелей'!$AT$3) -> 6430 | AE4: =IF(AD4="","",ROUND(AD4/(1+P4),0)) -> 5543 | AF4: =IF(AE4="","",AE4-X4) -> 2774 | AG4: =IF(OR(AE4="",AE4=0),"",AF4/AE4) -> 0.50045102 | AH4: =IF(AE4="",0,AE4*J4) -> 55430 | AI4: =IF(AF4="",0,AF4*J4) -> 27740 | AJ4: Заказано | AK4: =IFERROR(IF(INDEX('Сводка заказов'!$V$5:$V$24,MATCH($A4,'Сводка заказов'!$A$5:$A$24,0))="","",INDEX('Сводка заказов'!$V$5:$V$24,MATCH($A4,'Сводка заказов'!$A$5:$A$24,0))),"") -> 46323 | AN4: =IF(N(AL4)=0,"Нет",IF(AL4>=J4,"Да","Частично")) -> Нет | AO4: =J4-N(AL4) -> 10
A5: SDN-1 | B5: =IFERROR(INDEX('Сводка заказов'!$B$5:$B$24,MATCH($A5,'Сводка заказов'!$A$5:$A$24,0)),"") -> Ningbo Sidana | C5: =IFERROR(IF(INDEX('Сводка заказов'!$D$5:$D$24,MATCH($A5,'Сводка заказов'!$A$5:$A$24,0))="","",INDEX('Сводка заказов'!$D$5:$D$24,MATCH($A5,'Сводка заказов'!$A$5:$A$24,0))),"") -> 46286 | D5: 3 | F5: AKO-GV-002 | G5: ='ГИЛЬЗЫ И ВТУЛКИ'!$E$4 -> Овальная алюминиевая обжимная гильза 40х45х29 мм для каната Ø16 мм | H5: Dual Rope Clamp (customized) | I5: — | J5: 2000 | K5: шт | L5: 1.98 | M5: =J5*L5 -> 3960 | N5: 7616 99 900 8 | O5: =IFERROR(VLOOKUP($N5,'ТН ВЭД'!$A$4:$C$40,3,0),0) -> 0.09 | P5: =Справочники!$B$12 -> 0.16 | Q5: =ROUND(L5*Справочники!$B$5,2) -> 135.63 | R5: =ROUND(Q5*N(IFERROR(INDEX('Сводка заказов'!$Q$5:$Q$24,MATCH($A5,'Сводка заказов'!$A$5:$A$24,0)),0)),2) -> 0 | S5: =ROUND(Q5*N(IFERROR(INDEX('Сводка заказов'!$R$5:$R$24,MATCH($A5,'Сводка заказов'!$A$5:$A$24,0)),0)),2) -> 0 | T5: =Q5+R5+S5 -> 135.63 | U5: =ROUND(T5*O5,2) -> 12.21 | V5: =ROUND((T5+U5)*P5,2) -> 23.65 | W5: =ROUND(Q5*N(IFERROR(INDEX('Сводка заказов'!$S$5:$S$24,MATCH($A5,'Сводка заказов'!$A$5:$A$24,0)),0)),2) -> 20.34 | X5: =ROUND(T5+U5+W5+IF(Справочники!$B$22="Да",0,V5),0) -> 168 | Y5: =X5*J5 -> 336000 | Z5: =U5*J5 -> 24420 | AA5: =V5*J5 -> 47300 | AB5: =IF('ГИЛЬЗЫ И ВТУЛКИ'!$AO$4="","",'ГИЛЬЗЫ И ВТУЛКИ'!$AO$4) -> 100.5 | AC5: =IF('ГИЛЬЗЫ И ВТУЛКИ'!$AR$4="","",'ГИЛЬЗЫ И ВТУЛКИ'!$AR$4) -> 618 | AD5: =IF('ГИЛЬЗЫ И ВТУЛКИ'!$AT$4="","",'ГИЛЬЗЫ И ВТУЛКИ'!$AT$4) -> 400 | AE5: =IF(AD5="","",ROUND(AD5/(1+P5),0)) -> 345 | AF5: =IF(AE5="","",AE5-X5) -> 177 | AG5: =IF(OR(AE5="",AE5=0),"",AF5/AE5) -> 0.51304348 | AH5: =IF(AE5="",0,AE5*J5) -> 690000 | AI5: =IF(AF5="",0,AF5*J5) -> 354000 | AJ5: Заказано | AK5: =IFERROR(IF(INDEX('Сводка заказов'!$V$5:$V$24,MATCH($A5,'Сводка заказов'!$A$5:$A$24,0))="","",INDEX('Сводка заказов'!$V$5:$V$24,MATCH($A5,'Сводка заказов'!$A$5:$A$24,0))),"") -> 46323 | AN5: =IF(N(AL5)=0,"Нет",IF(AL5>=J5,"Да","Частично")) -> Нет | AO5: =J5-N(AL5) -> 2000 | AP5: Customized. Тот же размер, что Type E в заказе 2-2 (34 / 16,5 / 40 мм)
A6: SDN-1 | B6: =IFERROR(INDEX('Сводка заказов'!$B$5:$B$24,MATCH($A6,'Сводка заказов'!$A$5:$A$24,0)),"") -> Ningbo Sidana | C6: =IFERROR(IF(INDEX('Сводка заказов'!$D$5:$D$24,MATCH($A6,'Сводка заказов'!$A$5:$A$24,0))="","",INDEX('Сводка заказов'!$D$5:$D$24,MATCH($A6,'Сводка заказов'!$A$5:$A$24,0))),"") -> 46286 | D6: 4 | F6: AKO-KT-001 | G6: ='Крепёж и такелаж'!$E$3 -> Соединительный хомут из алюминия для трубы Ø114 мм, H 50 мм | H6: Connecting Buckle, cube Ø114 mm | I6: — | J6: 100 | K6: шт | L6: 18.5 | M6: =J6*L6 -> 1850 | N6: 7616 99 900 8 | O6: =IFERROR(VLOOKUP($N6,'ТН ВЭД'!$A$4:$C$40,3,0),0) -> 0.09 | P6: =Справочники!$B$12 -> 0.16 | Q6: =ROUND(L6*Справочники!$B$5,2) -> 1267.25 | R6: =ROUND(Q6*N(IFERROR(INDEX('Сводка заказов'!$Q$5:$Q$24,MATCH($A6,'Сводка заказов'!$A$5:$A$24,0)),0)),2) -> 0 | S6: =ROUND(Q6*N(IFERROR(INDEX('Сводка заказов'!$R$5:$R$24,MATCH($A6,'Сводка заказов'!$A$5:$A$24,0)),0)),2) -> 0 | T6: =Q6+R6+S6 -> 1267.25 | U6: =ROUND(T6*O6,2) -> 114.05 | V6: =ROUND((T6+U6)*P6,2) -> 221.01 | W6: =ROUND(Q6*N(IFERROR(INDEX('Сводка заказов'!$S$5:$S$24,MATCH($A6,'Сводка заказов'!$A$5:$A$24,0)),0)),2) -> 190.09 | X6: =ROUND(T6+U6+W6+IF(Справочники!$B$22="Да",0,V6),0) -> 1571 | Y6: =X6*J6 -> 157100 | Z6: =U6*J6 -> 11405 | AA6: =V6*J6 -> 22101 | AB6: =IF('Крепёж и такелаж'!$AO$3="","",'Крепёж и такелаж'!$AO$3) | AC6: =IF('Крепёж и такелаж'!$AR$3="","",'Крепёж и такелаж'!$AR$3) | AD6: =IF('Крепёж и такелаж'!$AT$3="","",'Крепёж и такелаж'!$AT$3) -> 3650 | AE6: =IF(AD6="","",ROUND(AD6/(1+P6),0)) -> 3147 | AF6: =IF(AE6="","",AE6-X6) -> 1576 | AG6: =IF(OR(AE6="",AE6=0),"",AF6/AE6) -> 0.50079441 | AH6: =IF(AE6="",0,AE6*J6) -> 314700 | AI6: =IF(AF6="",0,AF6*J6) -> 157600 | AJ6: Заказано | AK6: =IFERROR(IF(INDEX('Сводка заказов'!$V$5:$V$24,MATCH($A6,'Сводка заказов'!$A$5:$A$24,0))="","",INDEX('Сводка заказов'!$V$5:$V$24,MATCH($A6,'Сводка заказов'!$A$5:$A$24,0))),"") -> 46323 | AN6: =IF(N(AL6)=0,"Нет",IF(AL6>=J6,"Да","Частично")) -> Нет | AO6: =J6-N(AL6) -> 100
A7: SDN-1 | B7: =IFERROR(INDEX('Сводка заказов'!$B$5:$B$24,MATCH($A7,'Сводка заказов'!$A$5:$A$24,0)),"") -> Ningbo Sidana | C7: =IFERROR(IF(INDEX('Сводка заказов'!$D$5:$D$24,MATCH($A7,'Сводка заказов'!$A$5:$A$24,0))="","",INDEX('Сводка заказов'!$D$5:$D$24,MATCH($A7,'Сводка заказов'!$A$5:$A$24,0))),"") -> 46286 | D7: 5 | F7: AKO-KT-002 | G7: ='Крепёж и такелаж'!$E$4 -> Трубный хомут из алюминия для трубы Ø114 мм | H7: Pipe Clamp Buckle, cube Ø114 mm | I7: — | J7: 100 | K7: шт | L7: 10 | M7: =J7*L7 -> 1000 | N7: 7616 99 900 8 | O7: =IFERROR(VLOOKUP($N7,'ТН ВЭД'!$A$4:$C$40,3,0),0) -> 0.09 | P7: =Справочники!$B$12 -> 0.16 | Q7: =ROUND(L7*Справочники!$B$5,2) -> 685 | R7: =ROUND(Q7*N(IFERROR(INDEX('Сводка заказов'!$Q$5:$Q$24,MATCH($A7,'Сводка заказов'!$A$5:$A$24,0)),0)),2) -> 0 | S7: =ROUND(Q7*N(IFERROR(INDEX('Сводка заказов'!$R$5:$R$24,MATCH($A7,'Сводка заказов'!$A$5:$A$24,0)),0)),2) -> 0 | T7: =Q7+R7+S7 -> 685 | U7: =ROUND(T7*O7,2) -> 61.65 | V7: =ROUND((T7+U7)*P7,2) -> 119.46 | W7: =ROUND(Q7*N(IFERROR(INDEX('Сводка заказов'!$S$5:$S$24,MATCH($A7,'Сводка заказов'!$A$5:$A$24,0)),0)),2) -> 102.75 | X7: =ROUND(T7+U7+W7+IF(Справочники!$B$22="Да",0,V7),0) -> 849 | Y7: =X7*J7 -> 84900 | Z7: =U7*J7 -> 6165 | AA7: =V7*J7 -> 11946 | AB7: =IF('Крепёж и такелаж'!$AO$4="","",'Крепёж и такелаж'!$AO$4) | AC7: =IF('Крепёж и такелаж'!$AR$4="","",'Крепёж и такелаж'!$AR$4) | AD7: =IF('Крепёж и такелаж'!$AT$4="","",'Крепёж и такелаж'!$AT$4) -> 1970 | AE7: =IF(AD7="","",ROUND(AD7/(1+P7),0)) -> 1698 | AF7: =IF(AE7="","",AE7-X7) -> 849 | AG7: =IF(OR(AE7="",AE7=0),"",AF7/AE7) -> 0.5 | AH7: =IF(AE7="",0,AE7*J7) -> 169800 | AI7: =IF(AF7="",0,AF7*J7) -> 84900 | AJ7: Заказано | AK7: =IFERROR(IF(INDEX('Сводка заказов'!$V$5:$V$24,MATCH($A7,'Сводка заказов'!$A$5:$A$24,0))="","",INDEX('Сводка заказов'!$V$5:$V$24,MATCH($A7,'Сводка заказов'!$A$5:$A$24,0))),"") -> 46323 | AN7: =IF(N(AL7)=0,"Нет",IF(AL7>=J7,"Да","Частично")) -> Нет | AO7: =J7-N(AL7) -> 100
A8: SDN-1 | B8: =IFERROR(INDEX('Сводка заказов'!$B$5:$B$24,MATCH($A8,'Сводка заказов'!$A$5:$A$24,0)),"") -> Ningbo Sidana | C8: =IFERROR(IF(INDEX('Сводка заказов'!$D$5:$D$24,MATCH($A8,'Сводка заказов'!$A$5:$A$24,0))="","",INDEX('Сводка заказов'!$D$5:$D$24,MATCH($A8,'Сводка заказов'!$A$5:$A$24,0))),"") -> 46286 | D8: 6 | F8: AKO-KT-003 | G8: ='Крепёж и такелаж'!$E$5 -> Скоба такелажная D-образная из нержавеющей стали М10 | H8: Stainless steel D-shackle M10 | I8: — | J8: 600 | K8: шт | L8: 5.4 | M8: =J8*L8 -> 3240 | N8: 7326 90 980 7 | O8: =IFERROR(VLOOKUP($N8,'ТН ВЭД'!$A$4:$C$40,3,0),0) -> 0.075 | P8: =Справочники!$B$12 -> 0.16 | Q8: =ROUND(L8*Справочники!$B$5,2) -> 369.9 | R8: =ROUND(Q8*N(IFERROR(INDEX('Сводка заказов'!$Q$5:$Q$24,MATCH($A8,'Сводка заказов'!$A$5:$A$24,0)),0)),2) -> 0 | S8: =ROUND(Q8*N(IFERROR(INDEX('Сводка заказов'!$R$5:$R$24,MATCH($A8,'Сводка заказов'!$A$5:$A$24,0)),0)),2) -> 0 | T8: =Q8+R8+S8 -> 369.9 | U8: =ROUND(T8*O8,2) -> 27.74 | V8: =ROUND((T8+U8)*P8,2) -> 63.62 | W8: =ROUND(Q8*N(IFERROR(INDEX('Сводка заказов'!$S$5:$S$24,MATCH($A8,'Сводка заказов'!$A$5:$A$24,0)),0)),2) -> 55.49 | X8: =ROUND(T8+U8+W8+IF(Справочники!$B$22="Да",0,V8),0) -> 453 | Y8: =X8*J8 -> 271800 | Z8: =U8*J8 -> 16644 | AA8: =V8*J8 -> 38172 | AB8: =IF('Крепёж и такелаж'!$AO$5="","",'Крепёж и такелаж'!$AO$5) | AC8: =IF('Крепёж и такелаж'!$AR$5="","",'Крепёж и такелаж'!$AR$5) | AD8: =IF('Крепёж и такелаж'!$AT$5="","",'Крепёж и такелаж'!$AT$5) -> 1060 | AE8: =IF(AD8="","",ROUND(AD8/(1+P8),0)) -> 914 | AF8: =IF(AE8="","",AE8-X8) -> 461 | AG8: =IF(OR(AE8="",AE8=0),"",AF8/AE8) -> 0.50437637 | AH8: =IF(AE8="",0,AE8*J8) -> 548400 | AI8: =IF(AF8="",0,AF8*J8) -> 276600 | AJ8: Заказано | AK8: =IFERROR(IF(INDEX('Сводка заказов'!$V$5:$V$24,MATCH($A8,'Сводка заказов'!$A$5:$A$24,0))="","",INDEX('Сводка заказов'!$V$5:$V$24,MATCH($A8,'Сводка заказов'!$A$5:$A$24,0))),"") -> 46323 | AN8: =IF(N(AL8)=0,"Нет",IF(AL8>=J8,"Да","Частично")) -> Нет | AO8: =J8-N(AL8) -> 600
A9: SDN-1 | B9: =IFERROR(INDEX('Сводка заказов'!$B$5:$B$24,MATCH($A9,'Сводка заказов'!$A$5:$A$24,0)),"") -> Ningbo Sidana | C9: =IFERROR(IF(INDEX('Сводка заказов'!$D$5:$D$24,MATCH($A9,'Сводка заказов'!$A$5:$A$24,0))="","",INDEX('Сводка заказов'!$D$5:$D$24,MATCH($A9,'Сводка заказов'!$A$5:$A$24,0))),"") -> 46286 | D9: 7 | F9: AKO-KT-004 | G9: ='Крепёж и такелаж'!$E$6 -> Скоба такелажная из нержавеющей стали с винтом М10 | H9: Bow Shackle M10 (stainless) | I9: — | J9: 500 | K9: шт | L9: 7.2 | M9: =J9*L9 -> 3600 | N9: 7326 90 980 7 | O9: =IFERROR(VLOOKUP($N9,'ТН ВЭД'!$A$4:$C$40,3,0),0) -> 0.075 | P9: =Справочники!$B$12 -> 0.16 | Q9: =ROUND(L9*Справочники!$B$5,2) -> 493.2 | R9: =ROUND(Q9*N(IFERROR(INDEX('Сводка заказов'!$Q$5:$Q$24,MATCH($A9,'Сводка заказов'!$A$5:$A$24,0)),0)),2) -> 0 | S9: =ROUND(Q9*N(IFERROR(INDEX('Сводка заказов'!$R$5:$R$24,MATCH($A9,'Сводка заказов'!$A$5:$A$24,0)),0)),2) -> 0 | T9: =Q9+R9+S9 -> 493.2 | U9: =ROUND(T9*O9,2) -> 36.99 | V9: =ROUND((T9+U9)*P9,2) -> 84.83 | W9: =ROUND(Q9*N(IFERROR(INDEX('Сводка заказов'!$S$5:$S$24,MATCH($A9,'Сводка заказов'!$A$5:$A$24,0)),0)),2) -> 73.98 | X9: =ROUND(T9+U9+W9+IF(Справочники!$B$22="Да",0,V9),0) -> 604 | Y9: =X9*J9 -> 302000 | Z9: =U9*J9 -> 18495 | AA9: =V9*J9 -> 42415 | AB9: =IF('Крепёж и такелаж'!$AO$6="","",'Крепёж и такелаж'!$AO$6) -> 560 | AC9: =IF('Крепёж и такелаж'!$AR$6="","",'Крепёж и такелаж'!$AR$6) -> 3443 | AD9: =IF('Крепёж и такелаж'!$AT$6="","",'Крепёж и такелаж'!$AT$6) -> 3168 | AE9: =IF(AD9="","",ROUND(AD9/(1+P9),0)) -> 2731 | AF9: =IF(AE9="","",AE9-X9) -> 2127 | AG9: =IF(OR(AE9="",AE9=0),"",AF9/AE9) -> 0.77883559 | AH9: =IF(AE9="",0,AE9*J9) -> 1365500 | AI9: =IF(AF9="",0,AF9*J9) -> 1063500 | AJ9: Заказано | AK9: =IFERROR(IF(INDEX('Сводка заказов'!$V$5:$V$24,MATCH($A9,'Сводка заказов'!$A$5:$A$24,0))="","",INDEX('Сводка заказов'!$V$5:$V$24,MATCH($A9,'Сводка заказов'!$A$5:$A$24,0))),"") -> 46323 | AN9: =IF(N(AL9)=0,"Нет",IF(AL9>=J9,"Да","Частично")) -> Нет | AO9: =J9-N(AL9) -> 500
A10: SDN-1 | B10: =IFERROR(INDEX('Сводка заказов'!$B$5:$B$24,MATCH($A10,'Сводка заказов'!$A$5:$A$24,0)),"") -> Ningbo Sidana | C10: =IFERROR(IF(INDEX('Сводка заказов'!$D$5:$D$24,MATCH($A10,'Сводка заказов'!$A$5:$A$24,0))="","",INDEX('Сводка заказов'!$D$5:$D$24,MATCH($A10,'Сводка заказов'!$A$5:$A$24,0))),"") -> 46286 | D10: 8 | F10: AKO-KR-002 | G10: ='Крепление для качелей'!$E$4 -> Крепление для качелей из нержавеющей стали 120×110 мм | H10: Swing Buckle 12×11 cm (stainless) | I10: — | J10: 10 | K10: шт | L10: 98 | M10: =J10*L10 -> 980 | N10: 7326 90 980 7 | O10: =IFERROR(VLOOKUP($N10,'ТН ВЭД'!$A$4:$C$40,3,0),0) -> 0.075 | P10: =Справочники!$B$12 -> 0.16 | Q10: =ROUND(L10*Справочники!$B$5,2) -> 6713 | R10: =ROUND(Q10*N(IFERROR(INDEX('Сводка заказов'!$Q$5:$Q$24,MATCH($A10,'Сводка заказов'!$A$5:$A$24,0)),0)),2) -> 0 | S10: =ROUND(Q10*N(IFERROR(INDEX('Сводка заказов'!$R$5:$R$24,MATCH($A10,'Сводка заказов'!$A$5:$A$24,0)),0)),2) -> 0 | T10: =Q10+R10+S10 -> 6713 | U10: =ROUND(T10*O10,2) -> 503.48 | V10: =ROUND((T10+U10)*P10,2) -> 1154.64 | W10: =ROUND(Q10*N(IFERROR(INDEX('Сводка заказов'!$S$5:$S$24,MATCH($A10,'Сводка заказов'!$A$5:$A$24,0)),0)),2) -> 1006.95 | X10: =ROUND(T10+U10+W10+IF(Справочники!$B$22="Да",0,V10),0) -> 8223 | Y10: =X10*J10 -> 82230 | Z10: =U10*J10 -> 5034.8 | AA10: =V10*J10 -> 11546.4 | AB10: =IF('Крепление для качелей'!$AO$4="","",'Крепление для качелей'!$AO$4) | AC10: =IF('Крепление для качелей'!$AR$4="","",'Крепление для качелей'!$AR$4) | AD10: =IF('Крепление для качелей'!$AT$4="","",'Крепление для качелей'!$AT$4) -> 19080 | AE10: =IF(AD10="","",ROUND(AD10/(1+P10),0)) -> 16448 | AF10: =IF(AE10="","",AE10-X10) -> 8225 | AG10: =IF(OR(AE10="",AE10=0),"",AF10/AE10) -> 0.5000608 | AH10: =IF(AE10="",0,AE10*J10) -> 164480 | AI10: =IF(AF10="",0,AF10*J10) -> 82250 | AJ10: Заказано | AK10: =IFERROR(IF(INDEX('Сводка заказов'!$V$5:$V$24,MATCH($A10,'Сводка заказов'!$A$5:$A$24,0))="","",INDEX('Сводка заказов'!$V$5:$V$24,MATCH($A10,'Сводка заказов'!$A$5:$A$24,0))),"") -> 46323 | AN10: =IF(N(AL10)=0,"Нет",IF(AL10>=J10,"Да","Частично")) -> Нет | AO10: =J10-N(AL10) -> 10
A11: SDN-1 | B11: =IFERROR(INDEX('Сводка заказов'!$B$5:$B$24,MATCH($A11,'Сводка заказов'!$A$5:$A$24,0)),"") -> Ningbo Sidana | C11: =IFERROR(IF(INDEX('Сводка заказов'!$D$5:$D$24,MATCH($A11,'Сводка заказов'!$A$5:$A$24,0))="","",INDEX('Сводка заказов'!$D$5:$D$24,MATCH($A11,'Сводка заказов'!$A$5:$A$24,0))),"") -> 46286 | D11: 9 | F11: AKO-IK-015 | G11: ='Изделия для каната'!$E$17 -> Нейлоновое кольцо-вкладыш под М10 для каната Ø16 мм | H11: Nylon Core Ring M10 for 16 mm rope | I11: по фото: зелёный | J11: 500 | K11: шт | L11: 1.8 | M11: =J11*L11 -> 900 | N11: 3926 90 970 9 | O11: =IFERROR(VLOOKUP($N11,'ТН ВЭД'!$A$4:$C$40,3,0),0) -> 0.065 | P11: =Справочники!$B$12 -> 0.16 | Q11: =ROUND(L11*Справочники!$B$5,2) -> 123.3 | R11: =ROUND(Q11*N(IFERROR(INDEX('Сводка заказов'!$Q$5:$Q$24,MATCH($A11,'Сводка заказов'!$A$5:$A$24,0)),0)),2) -> 0 | S11: =ROUND(Q11*N(IFERROR(INDEX('Сводка заказов'!$R$5:$R$24,MATCH($A11,'Сводка заказов'!$A$5:$A$24,0)),0)),2) -> 0 | T11: =Q11+R11+S11 -> 123.3 | U11: =ROUND(T11*O11,2) -> 8.01 | V11: =ROUND((T11+U11)*P11,2) -> 21.01 | W11: =ROUND(Q11*N(IFERROR(INDEX('Сводка заказов'!$S$5:$S$24,MATCH($A11,'Сводка заказов'!$A$5:$A$24,0)),0)),2) -> 18.5 | X11: =ROUND(T11+U11+W11+IF(Справочники!$B$22="Да",0,V11),0) -> 150 | Y11: =X11*J11 -> 75000 | Z11: =U11*J11 -> 4005 | AA11: =V11*J11 -> 10505 | AB11: =IF('Изделия для каната'!$AO$17="","",'Изделия для каната'!$AO$17) | AC11: =IF('Изделия для каната'!$AR$17="","",'Изделия для каната'!$AR$17) | AD11: =IF('Изделия для каната'!$AT$17="","",'Изделия для каната'!$AT$17) -> 350 | AE11: =IF(AD11="","",ROUND(AD11/(1+P11),0)) -> 302 | AF11: =IF(AE11="","",AE11-X11) -> 152 | AG11: =IF(OR(AE11="",AE11=0),"",AF11/AE11) -> 0.50331126 | AH11: =IF(AE11="",0,AE11*J11) -> 151000 | AI11: =IF(AF11="",0,AF11*J11) -> 76000 | AJ11: Заказано | AK11: =IFERROR(IF(INDEX('Сводка заказов'!$V$5:$V$24,MATCH($A11,'Сводка заказов'!$A$5:$A$24,0))="","",INDEX('Сводка заказов'!$V$5:$V$24,MATCH($A11,'Сводка заказов'!$A$5:$A$24,0))),"") -> 46323 | AN11: =IF(N(AL11)=0,"Нет",IF(AL11>=J11,"Да","Частично")) -> Нет | AO11: =J11-N(AL11) -> 500 | AP11: Цвет в договоре не указан
